Workbook

Sheet Capa
A53: Nota: Neste ficheiro são disponiblizados os dados subjacentes aos gráficos e quadros do Boletim Económico – junho 2024. Note: This file contains the data used in the charts and tables of the Economic Bulletin – june 2024.

Sheet Índice
B1: Classificação de Segurança - Público
A5: Boletim Económico - junho 2024/Economic Bulletin June 2024
A6: ÍNDICE/CONTENTS
A7: Parte I. Projeções para a economia portuguesa: 2024-26/Part I. Projections for the Portuguese economy: 2024-26
A8: =HYPERLINK("#"&C8,INDIRECT(C8)) -> Quadro I.1.1 • Projeções do Banco de Portugal para 2024-26 | Taxa de variação anual, em percentagem (exceto onde indicado) | C8: QI.1.1!A$10
A9: =HYPERLINK("#"&C9,INDIRECT(C9)) -> Table I.1.1 • Projections of Banco de Portugal for 2024-26| Annual rate of change, in percentage (unless otherwise stated) | C9: QI.1.1!A$11
A10: =HYPERLINK("#"&C10,INDIRECT(C10)) -> Gráfico I.1.1 • PIB em Portugal e na área do euro | C10: GI.1.1!A$10
A11: =HYPERLINK("#"&C11,INDIRECT(C11)) -> Chart I.1.1 • GDP in Portugal and the euro area | C11: GI.1.1!A$11
A12: =HYPERLINK("#"&C12,INDIRECT(C12)) -> Gráfico I.1.2 • Projeções trimestrais para o PIB e para a inflação | C12: GI.1.2!A$10
A13: =HYPERLINK("#"&C13,INDIRECT(C13)) -> Chart I.1.2 • Quarterly GDP and inflation projections | C13: GI.1.2!A$11
A14: =HYPERLINK("#"&C14,INDIRECT(C14)) -> Gráfico I.1.3 • Taxa de variação do PIB e contributos líquidos de conteúdos importados das componentes | Percentagem e pontos percentuais | C14: GI.1.3!A$10
A15: =HYPERLINK("#"&C15,INDIRECT(C15)) -> Chart I.1.3 • GDP rate of change and import-content net contributions of components | Percentage and percentage points | C15: GI.1.3!A$11
A16: =HYPERLINK("#"&C16,INDIRECT(C16)) -> Gráfico I.1.4 • Consumo privado e rendimento disponível | Taxa de variação em percentagem e contributos para o rendimento disponível em pontos percentuais | C16: GI.1.4!A$10
A17: =HYPERLINK("#"&C17,INDIRECT(C17)) -> Chart I.1.4 • Private consumption and disposable income | Rate of change in percentage and contributions to disposable income in percentage points | C17: GI.1.4!A$11
A18: =HYPERLINK("#"&C18,INDIRECT(C18)) -> Gráfico I.1.5 • FBCF e componentes| Taxa de variação em percentagem | C18: GI.1.5!A$10
A19: =HYPERLINK("#"&C19,INDIRECT(C19)) -> Chart I.1.5 • GFCF and components| Rate of change in percentage | C19: GI.1.5!A$11
... A23: =HYPERLINK("#"&C23,INDIRECT(C23)) -> Chart I.1.7 • Observed HICP | Rate of change in percentage and contributions in percentage points | C23: GI.1.7!A$11
A25: Caixa 1- Enquadramento e políticas/Box 1-External environment, financing conditions and policies
A26: =HYPERLINK("#"&C26,INDIRECT(C26)) -> Gráfico C1.1 • IHPC e indicador PMI para o preço dos inputs na área do euro | Taxa de variação em cadeia anualizada sobre dados corrigidos de variações sazonais e em média móvel de 3 meses | C26: GC.1.1!A$10
A27: =HYPERLINK("#"&C27,INDIRECT(C27)) -> Chart B1.1 • HICP and PMI indicator for the price of inputs in the euro area | Annualized quarter-on-quarter variation rate of 3-month moving average and seasonally adjusted data | C27: GC.1.1!A$11
A28: =HYPERLINK("#"&C28,INDIRECT(C28)) -> Quadro C1.1 • Hipóteses do exercício de projeção elaboradas por especialistas do Eurosistema | C28: QC.1.1!A$10
A29: =HYPERLINK("#"&C29,INDIRECT(C29)) -> Table B1.1 • Eurosystem staff projection assumptions | C29: QC.1.1!A$11
A31: Caixa 2-Termos de troca no comércio de bens /Box 2-Terms of trade in goods
A32: =HYPERLINK("#"&C32,INDIRECT(C32)) -> Gráfico C2.1 • Termos de troca | Índice 2015 = 100 | C32: GC.2.1!A$10
A33: =HYPERLINK("#"&C33,INDIRECT(C33)) -> Chart B2.1 • Terms of trade | Index 2015 = 100 | C33: GC.2.1!A$11
A34: =HYPERLINK("#"&C34,INDIRECT(C34)) -> Gráfico C2.2 • Variação dos termos de troca de bens – contributos da componente energética e não energética | Em pontos percentuais | C34: GC.2.2!A$10
A35: =HYPERLINK("#"&C35,INDIRECT(C35)) -> Chart B2.2 • Terms of trade in goods change – contributions of energy and non-energy | In percentage points | C35: GC.2.2!A$11
A36: =HYPERLINK("#"&C36,INDIRECT(C36)) -> Gráfico C2.3 • Variação de termos de troca de bens e contributos dos efeitos estrutura e preço relativo | Em pontos percentuais | C36: GC.2.3!A$10
A37: =HYPERLINK("#"&C37,INDIRECT(C37)) -> Chart B2.3 • Terms of trade in goods change and contributions of structure and relative price effects | In percentage points | C37: GC.2.3!A$11
A38: =HYPERLINK("#"&C38,INDIRECT(C38)) -> Quadro C2.1 • Contributos dos grupos de produtos para a variação dos termos de troca de bens – 2023 vs. 2015 | Variação acumulada em percentagem e contributos em pp | C38: QC.2.1!A$10
A39: =HYPERLINK("#"&C39,INDIRECT(C39)) -> Table B2.1 • Groups of products' contribution to the terms of trade total variation – 2023 vs. 2015 | Cumulative growth as a percentage and contributions in pp | C39: QC.2.1!A$11
A41: Caixa 3 - A transmissão do preço dos bens energéticos ao IHPC / Box 3- The pass-through of energy prices to the HICP
A42: =HYPERLINK("#"&C42,INDIRECT(C42)) -> Gráfico C3.1 • IHPC total e IHPC de bens energéticos | Taxa de variação homóloga em percentagem e contributos em pontos percentuais | C42: GC.3.1!A$10
A43: =HYPERLINK("#"&C43,INDIRECT(C43)) -> Chart B3.1 • HICP headline and HICP of energy goods | Year-on-year change rate in percentage and contributions in percentage points | C43: GC.3.1!A$11
A44: =HYPERLINK("#"&C44,INDIRECT(C44)) -> Gráfico C3.2 • Resposta da inflação e dos seus componentes a um choque de 1 desvio padrão no preço dos bens energéticos | Pontos percentuais | C44: GC.3.2!A$10
A45: =HYPERLINK("#"&C45,INDIRECT(C45)) -> Chart B3.2 • Response of inflation and its components to a shock of 1 standard deviation in energy prices | Percentage points | C45: GC.3.2!A$11
A46: =HYPERLINK("#"&C46,INDIRECT(C46)) -> Gráfico C3.3 • Decomposição histórica da inflação e contributos diretos e indiretos dos choques estruturais sobre o preço dos bens energéticos | Taxa de variação homóloga em percentagem e contributos erm pontos percentuais | C46: GC.3.3!A$10
A47: =HYPERLINK("#"&C47,INDIRECT(C47)) -> Chart B3.3 • Historical decomposition of inflation and direct and indirect contributes of structural shocks to energy prices | Y-o-y rate of change in percentage and contributions in percentage points | C47: GC.3.3!A$11
A48: =HYPERLINK("#"&C48,INDIRECT(C48)) -> Quadro C3.1 • Contributo para a inflação dos choques estruturais sobre o preço da energia | Pontos percentuais | C48: QC.3.1!A$10
A49: =HYPERLINK("#"&C49,INDIRECT(C49)) -> Table B3.1 • Contribution to inflation from structural energy price shocks | Percentage points | C49: QC.3.1!A$11
...

Sheet QI.1.1
A5: Índice/Contents
A6: Boletim Económico - junho 2024/Economic Bulletin - June 2024
A7: =+Índice!$A$7 -> Parte I. Projeções para a economia portuguesa: 2024-26/Part I. Projections for the Portuguese economy: 2024-26
A10: Quadro I.1.1 • Projeções do Banco de Portugal para 2024-26 | Taxa de variação anual, em percentagem (exceto onde indicado)
A11: Table I.1.1 • Projections of Banco de Portugal for 2024-26| Annual rate of change, in percentage (unless otherwise stated)
A13: Unidade/Unit | C13: % | E13: % | F13: % | G13: % | H13: % | J13: % | K13: % | L13: % | M13: %
C14: Pesos | E14: BE Junho 2024 | J14: BE março 2023
C15: Weights | E15: EB June 2024 | J15: EB March 2023
C16: 2023 | E16: 2023 | F16: 2024(p) | G16: 2025(p) | H16: 2026(p) | J16: 2023 | K16: 2024(p) | L16: 2025(p) | M16: 2026(p)
A18: Produto interno bruto | B18: Gross domestic product | C18: 100 | E18: 2.2612549 | F18: 2.0372004 | G18: 2.2937181 | H18: 2.2337036 | J18: 2.28052 | K18: 2.0459739 | L18: 2.2967685 | M18: 2.2083861
A20: Consumo privado | B20: Private consumption | C20: 62.58191 | E20: 1.6617568 | F20: 1.9717615 | G20: 1.9311053 | H20: 1.8154847 | J20: 1.6336574 | K20: 2.0820899 | L20: 1.925106 | M20: 1.826615
A21: Consumo público | B21: Public consumption | C21: 16.996436 | E21: 1.0266231 | F21: 0.96740315 | G21: 0.87291352 | H21: 0.76134258 | J21: 1.2415149 | K21: 1.1926705 | L21: 0.877828 | M21: 0.92772281
A22: Formação bruta de capital fixo | B22: Gross fixed capital formation | C22: 19.386689 | E22: 2.549435 | F22: 3.2525603 | G22: 6.0710454 | H22: 4.9521543 | J22: 2.4401542 | K22: 3.6218192 | L22: 5.4391424 | M22: 4.119236
A23: Procura interna | B23: Domestic demand | C23: 99.167649 | E23: 1.4219138 | F23: 2.0924277 | G23: 2.5494514 | H23: 2.2508795 | J23: 1.4102447 | K23: 2.3656595 | L23: 2.4059002 | M23: 2.1184762
A24: Exportações | B24: Exports | C24: 47.441435 | E24: 4.1133954 | F24: 4.1742382 | G24: 3.7089045 | H24: 3.421961 | J24: 4.1830157 | K24: 3.5118923 | L24: 4.0090788 | M24: 3.2996928
A25: Importações | B25: Imports | C25: 46.609083 | E25: 2.2310907 | F25: 4.3102589 | G25: 4.2879151 | H25: 3.4617254 | J25: 2.2315081 | K25: 4.2144287 | L25: 4.2560516 | M25: 3.1101558
A27: Emprego (a) | B27: Employment (a) | E27: 0.8631955 | F27: 1.0084136 | G27: 0.81855017 | H27: 0.82481965 | J27: 0.8631955 | K27: 0.69846792 | L27: 0.58508385 | M27: 0.45415575
A28: Taxa de desemprego (b) | B28: Unemployment rate (b) | E28: 6.5091485 | F28: 6.5055283 | G28: 6.5640297 | H28: 6.5754342 | J28: 6.5091485 | K28: 6.5148295 | L28: 6.4592335 | M28: 6.4636811
A30: Balança corrente e de capital (% PIB) | B30: Current and capital account (% of GDP) | E30: 2.7280503 | F30: 4.3549206 | G30: 4.3898441 | H30: 4.5446319 | J30: 2.7255972 | K30: 3.595957 | L30: 3.8835519 | M30: 4.08046
A31: Balança de bens e serviços (% PIB) | B31: Trade balance (% of GDP) | E31: 1.2338337 | F31: 2.3555582 | G31: 1.8443429 | H31: 2.0570994 | J31: 1.2327243 | K31: 1.1249379 | L31: 1.2303927 | M31: 1.4790873
A33: Índice harmonizado de preços no consumidor | B33: Harmonised index of consumer prices | E33: 5.2642832 | F33: 2.4906724 | G33: 2.0875933 | H33: 1.9766928 | J33: 5.2642832 | K33: 2.3577992 | L33: 1.9997807 | M33: 1.9371263
A34: Bens energéticos | B34: Energy | E34: -8.9092019 | F34: 1.9157348 | G34: 0.36758997 | H34: -0.64928961 | J34: -8.9092019 | K34: 3.6141984 | L34: 2.1580193 | M34: 0.58776934
A35: Bens alimentares | B35: Food | E35: 9.2039871 | F35: 3.1165032 | G35: 1.8286636 | H35: 1.6695415 | J35: 9.2039871 | K35: 3.0211879 | L35: 1.2980433 | M35: 1.5113193
A36: Excluindo bens energéticos | B36: Excluding energy | E36: 6.5476591 | F36: 2.5256115 | G36: 2.1940549 | H36: 2.13566 | J36: 6.5476591 | K36: 2.2791734 | L36: 1.9902956 | M36: 2.022027
A37: Excluindo bens energéticos e alimentares | B37: Excluding energy and food | E37: 5.3698003 | F37: 2.3197031 | G37: 2.3174846 | H37: 2.2952439 | J37: 5.3698003 | K37: 2.0207849 | L37: 2.2275851 | M37: 2.1964871
A39: Saldo orçamental (% PIB) | B39: Budget Balance (% of GDP) | E39: 1.202813 | F39: 1.0381781 | G39: 0.77930605 | H39: 0.64383201 | J39: - | K39: - | L39: - | M39: -
A40: Dívida Pública (% PIB) | B40: Public Debt (% GDP) | E40: 99.089226 | F40: 92.486423 | G40: 87.220414 | H40: 82.658473 | J40: - | K40: - | L40: - | M40: -
A42: Fontes: Banco de Portugal e INE. | Notas: (p) – projetado. As atuais projeções enquadram-se no exercício de projeção do Eurosistema de junho de 2024, com fecho de dados a 21 de maio e divulgado no dia 6 de junho. A projeção corresponde ao valor mais provável condicional ao conjunto de hipóteses consideradas. Pesos a preços correntes. (a) De acordo com o conceito de Contas Nacionais. (b) Em percentagem da população ativa.
A43: Sources: Banco de Portugal and Statistics Portugal. | Notes: (p) – projected. The current projections are part of the Eurosystem projection exercise of June 2024, with cut-off date for macroeconomic projections on May 21 and released on June 6. For each aggregate, this table shows the projection corresponding to the most likely value, conditional on the set of assumptions. (a) According to the national accounts concept. (b) In percentage of the labour force.

Sheet GI.1.1
A5: Índice/Contents
A6: Boletim Económico - junho 2024/Economic Bulletin - June 2024
A7: Parte I. Projeções para a economia portuguesa: 2024-26/Part I. Projections for the Portuguese economy: 2024-26
A10: Gráfico I.1.1 • PIB em Portugal e na área do euro
A11: Chart I.1.1 • GDP in Portugal and the euro area
A13: Unidade/Unit | B13: Índice 2019=100 | C13: Índice 2019=100 | D13: Índice 2019=100 | E13: Índice 2019=100 | F13: Índice 2019=100
B14: Index 2019=100 | C14: Index 2019=100 | D14: Index 2019=100 | E14: Index 2019=100 | F14: Index 2019=100
B16: Portugal | C16: Área do euro | D16: Mediana | E16: Intervalo interquartis
B17: Portugal | C17: Euro area | D17: Median | E17: Interquartile range
A18: 2019 | B18: 100 | C18: 100 | D18: 100 | E18: 100 | F18: 100
A19: 2020 | B19: 91.699484 | C19: 93.751694 | D19: 95.780866 | E19: 91.807287 | F19: 96.913746
A20: 2021 | B20: 96.960684 | C20: 99.271803 | D20: 101.66986 | E20: 98.430375 | F20: 104.26066
A21: 2022 | B21: 103.58068 | C21: 102.72392 | D21: 105.05827 | E21: 102.4386 | F21: 107.96164
A22: 2023 | B22: 105.92291 | C22: 103.30683 | D22: 105.819 | E22: 102.72625 | F22: 108.04658
A23: 2024 (p) | B23: 108.08077 | C23: 104.21247 | D23: 107.71928 | E23: 103.79074 | F23: 110.58718
A24: 2025 (p) | B24: 110.55984 | C24: 105.71737 | D24: 110.45496 | E24: 105.8614 | F24: 113.568
A25: 2026 (p) | B25: 113.02942 | C25: 107.38992 | D25: 113.07755 | E25: 108.08874 | F25: 116.84822
A28: Fonte: Eurosistema (exercício de projeção de junho de 2024). | Notas: (p) — projetado. A mediana e o intervalo interquartis referem-se aos 20 países que compõem a área do euro.
A29: Sources: Banco de Portugal and Statistics Portugal. | Notes: (p) – projected. The median and interquartile range refer to the 20 countries that make up the euro area.

Sheet GI.1.2
A5: Índice/Contents
A6: Boletim Económico - junho 2024/Economic Bulletin - June 2024
A7: Parte I. Projeções para a economia portuguesa: 2024-26/Part I. Projections for the Portuguese economy: 2024-26
A10: Gráfico I.1.2 • Projeções trimestrais para o PIB e para a inflação
A11: Chart I.1.2 • Quarterly GDP and inflation projections
A13: Unidade/Unit | C13: % | D13: % | E13: % | F13: % | G13: % | H13: % | I13: % | J13: % | K13: % | L13: % | M13: % | N13: % | O13: % | P13: % | Q13: % | R13: %
C14: 2023 T1 | D14: 2023 T2 | E14: 2023 T3 | F14: 2023 T4 | G14: 2024 T1 | H14: 2024 T2 | I14: 2024 T3 | J14: 2024 T4 | K14: 2025 T1 | L14: 2025 T2 | M14: 2025 T3 | N14: 2025 T4 | O14: 2026 T1 | P14: 2026 T2 | Q14: 2026 T3 | R14: 2026 T4
C15: 2023 Q1 | D15: 2023 Q2 | E15: 2023 Q3 | F15: 2023 Q4 | G15: 2024 Q1 | H15: 2024 Q2 | I15: 2024 Q3 | J15: 2024 Q4 | K15: 2025 Q1 | L15: 2025 Q2 | M15: 2025 Q3 | N15: 2025 Q4 | O15: 2026 Q1 | P15: 2026 Q2 | Q15: 2026 Q3 | R15: 2026 Q4
A17: Painel A - PIB - taxa de variação em cadeia | Percentagem | B17: Panel A - GDP - quarter-on-quarter rate of change | Percentage
A18: BE de Junho | B18: June EB | C18: 1.46429 | D18: 0.10359565 | E18: -0.22753633 | F18: 0.72057319 | G18: 0.68377563 | H18: 0.60021211 | I18: 0.59382077 | J18: 0.55435084 | K18: 0.6346271 | L18: 0.50438703 | M18: 0.54991071 | N18: 0.49654165 | O18: 0.52484377 | P18: 0.61664429 | Q18: 0.60668882 | R18: 0.60211556
A19: BE de Março | B19: March EB | C19: 1.460228 | D19: 0.087780531 | E19: -0.19607811 | F19: 0.79644871 | G19: 0.66983929 | H19: 0.55876798 | I19: 0.56552396 | J19: 0.55192475 | K19: 0.59769204 | L19: 0.58541301 | M19: 0.56310902 | N19: 0.49053571 | O19: 0.52966022 | P19: 0.58876109 | Q19: 0.57612743 | R19: 0.54041728
A21: Painel B - IHPC - taxa de variação homóloga | Percentagem | B21: Panel B - HICP - Year-on-year rate of change | Percentage | C21: 8.394319 | D21: 5.6535438 | E21: 4.8143413 | F21: 2.4454348 | G21: 2.4631669 | H21: 2.7491851 | I21: 2.3332742 | J21: 2.4171617 | K21: 1.9717338 | L21: 2.0294944 | M21: 2.2006849 | N21: 2.1452244 | O21: 2.0621914 | P21: 1.9488066 | Q21: 1.913581 | R21: 1.9848899
A22: BE de Junho | B22: June EB | C22: 8.394319 | D22: 5.6535438 | E22: 4.8143413 | F22: 2.4454348 | G22: 2.3345525 | H22: 2.6090358 | I22: 2.2353349 | J22: 2.2522741 | K22: 1.9240392 | L22: 1.8929787 | M22: 2.0596441 | N22: 2.1206954 | O22: 2.0855065 | P22: 1.9645688 | Q22: 1.8761986 | R22: 1.8264064
A23: BE de Março | B23: March EB
A26: Fontes: Banco de Portugal e INE. | Nota: As linhas a tracejado correspondem aos valores projetados nos BE de março e junho de 2024.
A27: Sources: Banco de Portugal and Statistics Portugal. | Note: The dashed lines correspond to the projected values in the EB of March and June 2024.

Sheet GI.1.3
A5: Índice/Contents
A6: Boletim Económico - junho 2024/Economic Bulletin - June 2024
A7: Parte I. Projeções para a economia portuguesa: 2024-26/Part I. Projections for the Portuguese economy: 2024-26
A10: Gráfico I.1.3 • Taxa de variação do PIB e contributos líquidos de conteúdos importados das componentes | Percentagem e pontos percentuais
A11: Chart I.1.3 • GDP rate of change and import-content net contributions of components | Percentage and percentage points
A13: Unidade/Unit | C13: % e pp | D13: % e pp | E13: % e pp | F13: % e pp | G13: % e pp | H13: % e pp | I13: % e pp
C14: % and pp | D14: % and pp | E14: % and pp | F14: % and pp | G14: % and pp | H14: % and pp | I14: % and pp
C16: 2015-2019 | D16: 2020-22 | F16: 2023 | G16: 2024 (p) | H16: 2025 (p) | I16: 2026 (p)
A18: PIB (em percentagem) | B18: GDP (percentage) | C18: 2.5699926 | D18: 1.4214771 | F18: 2.2612549 | G18: 2.0372004 | H18: 2.2937181 | I18: 2.2337036
A20: Exportações | B20: Exports | C20: 1.1442875 | D20: 0.81178613 | F20: 1.4230967 | G20: 0.94537747 | H20: 0.90067595 | I20: 0.88392726
A21: Investimento | B21: Investment | C21: 0.47522375 | D21: 0.1855418 | F21: 0.040863292 | G21: 0.29549085 | H21: 0.59525225 | I21: 0.51358366
A22: Consumo | B22: Consumption | C22: 0.97506987 | D22: 0.41528234 | F22: 0.79754734 | G22: 0.79925255 | H22: 0.79095605 | I22: 0.83619265
A25: Fontes: Banco de Portugal e INE. | Notas: (p) – projetado. Para informações sobre a metodologia de cálculo dos contributos líquidos de conteúdo importado, ver Cardoso e Rua (2021), “O real contributo da procura final para o crescimento do PIB”, Revista de Estudos Económicos do Banco de Portugal, Volume VII, nº 3.
A26: Sources: Banco de Portugal and Statistics Portugal. | Notes: (p) - projected. For information on the methodology for calculating import-content net contributions, see Cardoso and Rua (2021), “Unveiling the real contribution of final demand to GDP growth”, Banco de Portugal Economic Studies, Volume VII, no. 3.

Sheet GI.1.4
A5: Índice/Contents
A6: Boletim Económico - junho 2024/Economic Bulletin - June 2024
A7: Parte I. Projeções para a economia portuguesa: 2024-26/Part I. Projections for the Portuguese economy: 2024-26
A10: Gráfico I.1.4 • Consumo privado e rendimento disponível | Taxa de variação em percentagem e contributos para o rendimento disponível em pontos percentuais
A11: Chart I.1.4 • Private consumption and disposable income | Rate of change in percentage and contributions to disposable income in percentage points
A13: Unidade/Unit | C13: % e pp | D13: % e pp | E13: % e pp | F13: % e pp
C14: % and pp | D14: % and pp | E14: % and pp | F14: % and pp
C16: 2023 | D16: 2024 (p) | E16: 2025 (p) | F16: 2026 (p)
A19: Consumo privado nominal | B19: Nominal private consumption | C19: 6.8090786 | D19: 4.8407191 | E19: 4.1960294 | F19: 3.8345096
A20: Consumo privado em termos reais | B20: Private consumption in real terms | C20: 1.6617568 | D20: 1.9717615 | E20: 1.9311053 | F20: 1.8154847
A21: Deflator do consumo privado | B21: Private consumption deflator | C21: 5.063184 | D21: 2.8134824 | E21: 2.2220146 | F21: 1.9830234
A24: Rendimento disponível nominal | B24: Nominal disposable income | C24: 6.7787215 | D24: 6.8715616 | E24: 4.4755807 | F24: 3.7971855
A25: Contributo remunerações | B25: Contribution of compensation of employees | C25: 7.2992447 | D25: 4.8457656 | E25: 3.2026148 | F25: 3.1449428
A26: Contributo transferências internas | B26: Contribution of domestic transfers | C26: 1.4778004 | D26: 2.4164908 | E26: 1.282741 | F26: 0.96175666
A27: Contributo impostos diretos | B27: Contribution of direct taxes | C27: -1.0114927 | D27: -0.081449999 | E27: -0.39470355 | F27: -0.52377138
A28: Contributo outras componentes do rend. disponível | B28: Contribution of other disposable income components | C28: -0.98683088 | D28: -0.30924475 | E28: 0.38492851 | F28: 0.2142574
A29: Por memória: rendimento disponível real | B29: Memo: real disposable income | C29: 1.6328627 | D29: 3.9470302 | E29: 2.20458 | F29: 1.7788863
A34: Fontes: Banco de Portugal e INE. | Nota: (p) – projetado.
A35: Sources: Banco de Portugal and Statistics Portugal. | Note: (p) - projected.

Sheet GI.1.5
A5: Índice/Contents
A6: Boletim Económico - junho 2024/Economic Bulletin - June 2024
A7: Parte I. Projeções para a economia portuguesa: 2024-26/Part I. Projections for the Portuguese economy: 2024-26
A10: Gráfico I.1.5 • FBCF e componentes| Taxa de variação em percentagem
A11: Chart I.1.5 • GFCF and components| Rate of change in percentage
A13: Unidade/Unit | C13: % | D13: % | E13: % | F13: %
C16: 2023 | D16: 2024 (p) | E16: 2025 (p) | F16: 2026 (p)
A19: FBCF Total | B19: Total GFCF | C19: 2.549435 | D19: 3.2525603 | E19: 6.0710454 | F19: 4.9521543
A20: FBCF Pública | B20: Public GFCF | C20: 12.52833 | D20: 20.346989 | E20: 13.262595 | F20: 8.0639918
A21: FBCF Habitação | B21: Housing GFCF | C21: -1.0551081 | D21: -0.81162725 | E21: 1.7854008 | F21: 2.3257094
A22: FBCF Empresarial | B22: Business GFCF | C22: 1.7283411 | D22: 1.0606807 | E22: 5.4394936 | F22: 4.7732565
A29: Fontes: Banco de Portugal e INE. | Nota: (p) – projetado.
A30: Sources: Banco de Portugal and Statistics Portugal. | Note: (p) - projected.

Sheet GI.1.6
A5: Índice/Contents
A6: Boletim Económico - junho 2024/Economic Bulletin - June 2024
A7: Parte I. Projeções para a economia portuguesa: 2024-26/Part I. Projections for the Portuguese economy: 2024-26
A10: Gráfico I.1.6 • Comércio de bens e serviços | Taxa de variação em percentagem e contributos em pontos percentuais
A11: Chart I.1.6 • Trade in goods and services | Rate of change in percentage and contributions in percentage points
A13: Unidade/Unit | C13: % e pp | D13: % e pp | E13: % e pp | F13: % e pp
C14: % and pp | D14: % and pp | E14: % and pp | F14: % and pp
C16: 2023 | D16: 2024 (p) | E16: 2025 (p) | F16: 2026 (p)
A17: Painel A - Exportações de bens e serviços e componentes | B17: Panel A - Exports of goods and services and components
A19: Exportações de bens e serviços | B19: Exports of goods and services | C19: 4.1133954 | D19: 4.1742382 | E19: 3.7089045 | F19: 3.421961
A20: Bens | B20: Goods | C20: -0.18948561 | D20: 2.274322 | E20: 2.1394914 | F20: 2.0219345
A21: Serviços | B21: Services | C21: 4.302881 | D21: 1.8999162 | E21: 1.5694131 | F21: 1.4000266
A23: Por memória: procura externa de bens e serviços | B23: Memo: external demand for goods and services | C23: -0.50294917 | D23: 1.1456917 | E23: 3.1877117 | F23: 3.2420058
A26: Painel B - Importações de bens e serviços e componentes | B26: Panel B - Imports of goods and services and components
A28: Importações de bens e serviços | B28: Imports of goods and services | C28: 2.2310907 | D28: 4.3102589 | E28: 4.2879151 | F28: 3.4617254
A29: Bens | B29: Goods | C29: 1.2143785 | D29: 3.8978697 | E29: 3.4036396 | F29: 2.8066901
A30: Serviços | B30: Services | C30: 1.0167123 | D30: 0.41238915 | E30: 0.8842755 | F30: 0.65503522
A34: Fontes: Banco de Portugal e INE. | Notas: (p) — projetado. O indicador de procura externa dirigida à economia portuguesa consiste numa média das importações dos parceiros comerciais, ponderadas pelo seu peso nas exportações portuguesas.
A35: Sources: Banco de Portugal and Statistics Portugal. | Notes: (p) - projected. The indicator of external demand for the Portuguese economy consists of an average of imports of trading partners, weighted by their share in Portuguese exports.

Sheet GI.1.7
A5: Índice/Contents
A6: Boletim Económico - junho 2024/Economic Bulletin - June 2024
A7: Parte I. Projeções para a economia portuguesa: 2024-26/Part I. Projections for the Portuguese economy: 2024-26
A10: Gráfico I.1.7 • IHPC observado | Taxa de variação homóloga em percentagem e contributos em pontos percentuais
A11: Chart I.1.7 • Observed HICP | Rate of change in percentage and contributions in percentage points
A13: Unidade/Unit | D13: pp | E13: pp | F13: pp | G13: pp | H13: %
D14: Energéticos | E14: Componentes voláteis associadas com o turismo | F14: Alto conteúdo importado | G14: Baixo conteúdo importado | H14: Total
D15: Energy | E15: Volatile components associated with tourism | F15: High import content | G15: Low import content | H15: Total
C17: 2021 T1 | D17: -0.11209262 | E17: -0.37285267 | F17: 0.29833102 | G17: 0.38213257 | H17: 0.1955183
C18: 2021 T2 | D18: 0.67544827 | E18: -1.6641169 | F18: 0.35712092 | G18: 0.56866183 | H18: -0.062885901
C19: 2021 T3 | D19: 0.75781326 | E19: -0.4592732 | F19: 0.3856595 | G19: 0.54777734 | H19: 1.2319769
C20: 2021 T4 | D20: 1.0244034 | E20: 0.19071791 | F20: 0.61950868 | G20: 0.58221659 | H20: 2.4168465
C21: 2022 T1 | D21: 1.2576848 | E21: 0.21202919 | F21: 1.9854147 | G21: 0.96378244 | H21: 4.4189111
C22: 2022 T2 | D22: 2.2509772 | E22: 1.0593612 | F22: 3.7851245 | G22: 1.0740176 | H22: 8.1694805
C23: 2022 T3 | D23: 2.0653286 | E23: 1.4654284 | F23: 4.8478054 | G23: 1.1495937 | H23: 9.5281561
C24: 2022 T4 | D24: 1.9624682 | E24: 0.862034 | F24: 6.0300666 | G24: 1.3502584 | H24: 10.204827
C25: 2023 T1 | D25: 0.20219231 | E25: 0.55039527 | F25: 5.9782067 | G25: 1.6685283 | H25: 8.3993225
C26: 2023 T2 | D26: -1.3296388 | E26: 1.5941982 | F26: 3.6877743 | G26: 1.6992299 | H26: 5.6515635
C27: 2023 T3 | D27: -0.72155623 | E27: 1.487275 | F27: 2.2554361 | G27: 1.792628 | H27: 4.8137828
C28: 2023 T4 | D28: -0.97902871 | E28: 0.69338929 | F28: 1.1005282 | G28: 1.6330589 | H28: 2.4479476
C29: 2024 T1 | D29: 0.17771255 | E29: 0.40964432 | F29: 0.10677144 | G29: 1.7673255 | H29: 2.4614538
A35: Fontes: Banco de Portugal e INE. | Notas: O conteúdo importado inclui o conteúdo direto e indireto do consumo privado em 2017. As rubricas do IHPC de elevado conteúdo importado correspondem às que se caraterizam por um conteúdo importado estimado superior a 20% na despesa de consumo. Para mais pormenores sobre o cálculo do IHPC por nível de conteúdo importado, ver o Boletim Económico de junho de 2022.
A36: Sources: Banco de Portugal and Statistics Portugal. | Notes: Import content includes the direct and indirect content of private consumption in 2017. HICP items with a high import content correspond to those with an estimated import content of more than 20% of consumption expenditure. For more details on calculating the HICP by level of import content, see the June 2022 Economic Bulletin.

Sheet GC.1.1
A5: Índice/Contents
A6: Boletim Económico - junho 2024/Economic Bulletin - June 2024
A10: Gráfico C1.1 • IHPC e indicador PMI para o preço dos inputs na área do euro | Taxa de variação em cadeia anualizada sobre dados corrigidos de variações sazonais e em média móvel de 3 meses
A11: Chart B1.1 • HICP and PMI indicator for the price of inputs in the euro area | Annualized quarter-on-quarter variation rate of 3-month moving average and seasonally adjusted data
A13: Unidade/Unit | C13: Taxa de variação em cadeia anualizada sobre dados corrigidos de variações sazonais e em média móvel de 3 meses /Annualized quarter-on-quarter variation rate of 3-month moving average and seasonally adjusted data
C15: Painel A - Bens excluindo alimentares e energéticos | F15: Painel B - Serviços
C16: Panel A - Goods excluding food and energy | F16: Panel B - Services
C18: IHPC - bens exc. alim. e energ. | D18: Média 2014-19 | E18: PMI - preço dos inputs na indústria (t-10) | F18: IHPC - serviços | G18: Média 2014-19 | H18: PMI - preço dos inputs nos serviços (t-6)
C19: HICP - goods exc. food and energy | D19: Average 2014-19 | E19: PMI - input prices in manufacturing (t-10) | F19: HICP - services | G19: Average 2014-20 | H19: PMI - input prices in services (t-6)
A20: 43831 | B20: 43831 | C20: 0.45658261 | D20: 0.29589648 | E20: 1.3233447 | F20: 0.94476582 | G20: 1.411748 | H20: 1.3654098
A21: 43862 | B21: 43862 | C21: 0.034011531 | D21: 0.29589648 | E21: 1.3880214 | F21: 0.80616159 | G21: 1.411748 | H21: 1.3989188
A22: 43891 | B22: 43891 | C22: -0.15914057 | D22: 0.29589648 | E22: 1.1680564 | F22: 0.35890392 | G22: 1.411748 | H22: 1.1968411
A23: 43922 | B23: 43922 | C23: 0.46843921 | D23: 0.29589648 | E23: 0.69689858 | F23: 0.68855991 | G23: 1.411748 | H23: 1.5055281
A24: 43952 | B24: 43952 | C24: 0.75936614 | D24: 0.29589648 | E24: 0.44543534 | F24: 0.58370302 | G24: 1.411748 | H24: 1.3991711
A25: 43983 | B25: 43983 | C25: 0.35109787 | D25: 0.29589648 | E25: 0.50051721 | F25: 1.1460347 | G25: 1.411748 | H25: 1.361361
A26: 44013 | B26: 44013 | C26: 1.4459925 | D26: 0.29589648 | E26: 0.44923701 | F26: 0.63313724 | G26: 1.411748 | H26: 1.5604505
A27: 44044 | B27: 44044 | C27: 0.55311533 | D27: 0.29589648 | E27: 0.061821181 | F27: 0.43647103 | G27: 1.411748 | H27: 1.3890758
A28: 44075 | B28: 44075 | C28: 0.43315059 | D28: 0.29589648 | E28: 0.097314466 | F28: -0.43886947 | G28: 1.411748 | H28: -0.1345115
A29: 44105 | B29: 44105 | C29: -3.0418966 | D29: 0.29589648 | E29: 0.25870921 | F29: -0.22243993 | G29: 1.411748 | H29: -1.2518741
A30: 44136 | B30: 44136 | C30: -1.997955 | D30: 0.29589648 | E30: 0.34767548 | F30: 0.14474396 | G30: 1.411748 | H30: -0.56436952
A31: 44166 | B31: 44166 | C31: -1.6091008 | D31: 0.29589648 | E31: 0.57243627 | F31: 1.1338766 | G31: 1.411748 | H31: 0.40067825
... A71: 45383 | B71: 45383 | C71: 0.82524938 | D71: 0.29589648 | E71: -0.54710758 | F71: 5.3012967 | G71: 1.411748 | H71: 2.5153871
A72: 45413 | B72: 45413 | D72: 0.29589648 | E72: -1.0901594 | G72: 1.411748 | H72: 2.6259844
A73: 45444 | B73: 45444 | D73: 0.29589648 | E73: -0.5142925 | G73: 1.411748 | H73: 2.4225253
A74: 45474 | B74: 45474 | D74: 0.29589648 | E74: -0.20106058 | G74: 1.411748 | H74: 2.6345504
A75: 45505 | B75: 45505 | D75: 0.29589648 | E75: -0.10524747 | G75: 1.411748 | H75: 2.7057783
A76: 45536 | B76: 45536 | D76: 0.29589648 | E76: -0.082660827 | G76: 1.411748 | H76: 2.3964694
A77: 45566 | B77: 45566 | D77: 0.29589648 | E77: -0.015605472 | G77: 1.411748 | H77: 2.4411968
A78: 45597 | B78: 45597 | D78: 0.29589648 | E78: -0.057620984 | G78: 1.411748
A79: 45627 | B79: 45627 | D79: 0.29589648 | E79: 0.33297148 | G79: 1.411748
A83: Fontes: Eurostat e S&P Global (cálculos do Banco de Portugal).| Notas: A taxa de variação em cadeia da média móvel a 3 meses considera informação do IHPC corrigido de variações sazonais num período de 6 meses, correspondendo à variação da média dos últimos 3 meses sobre a média do período de 3 meses imediatamente anterior. Os indicadores PMI para os preços dos inputs da indústria e dos serviços sofreram uma alteração de escala de maneira a apresentarem a mesma média e desvio-padrão do indicador de inflação subjacente correspondente, e foram desfasados 10 e 6 meses, respetivamente.
A84: Sources: Eurostat and S&P Global (Banco de Portugal calculations).| Notes: The quarter-on-quarter variation rate of the 3-month moving average considers information from the seasonally adjusted HIPC over a period of six months, corresponding to the variation of the average of the last 3 months over the average of the immediately preceding 3-month period. The scale of PMI indicators for input prices in manufacturing and services was changed so that they present the mean and standard deviation of the corresponding underlying inflation indicator, and were lagged by 10 and 6 months, respectively.

Sheet GC.1.2
A5: Índice/Contents
A6: Boletim Económico - junho 2024/Economic Bulletin - June 2024
A7: Caixa 1- Enquadramento e políticas/Box 1-External environment, financing conditions and policies
A10: Gráfico C1.2 • Hipóteses do exercício de projeção para o preço da energia e das outras matérias-primas e para a taxa de juro de curto prazo
A11: Chart B1.2 • Projection assumptions for the prices of energy and other commodities, and the short-term interest rate
A13: Unidade/Unit | C13: EUR/MWh | F13: 2005=100 | I13: Percentagem/Percentage
C14: Painel A - Indicador sintético do preço da energia (petróleo e gás) | F14: Painel B - Preço das matérias-primas exceto energia | I14: Painel C - Taxa de juro EURIBOR a 3 meses
C15: Panel A - Synthetic energy price index (oil and gas) | F15: Panel B - Non-oil commodity prices | I15: Panel C - Short-term interest rate (3-month EURIBOR)
C17: Observado | D17: 45444 | E17: 45352 | F17: Observado | G17: 45444 | H17: 45352 | I17: Observado | J17: 45444 | K17: 45352
C18: Observed | D18: 45444 | E18: 45352 | F18: Observed | G18: 45444 | H18: 45352 | I18: Observed | J18: 45444 | K18: 45352
A19: 2019Q1 | B19: 2019T1 | C19: 27.841998 | F19: -0.30856132 | I19: 152.84668
A20: 2019Q2 | B20: 2019T2 | C20: 28.467829 | F20: -0.31706087 | I20: 152.06765
A21: 2019Q3 | B21: 2019T3 | C21: 25.124432 | F21: -0.3967076 | I21: 149.86049
A22: 2019Q4 | B22: 2019T4 | C22: 26.87872 | F22: -0.40305176 | I22: 152.23398
A23: 2020Q1 | B23: 2020T1 | C23: 21.206444 | F23: -0.40542299 | I23: 151.28747
A24: 2020Q2 | B24: 2020T2 | C24: 11.608262 | F24: -0.29965152 | I24: 140.98916
A25: 2020Q3 | B25: 2020T3 | C25: 17.059312 | F25: -0.47173612 | I25: 151.24808
A26: 2020Q4 | B26: 2020T4 | C26: 19.310684 | F26: -0.52275146 | I26: 164.61918
A27: 2021Q1 | B27: 2021T1 | C27: 25.987589 | F27: -0.54241153 | I27: 189.86087
A28: 2021Q2 | B28: 2021T2 | C28: 30.773076 | F28: -0.54038023 | I28: 211.90862
A29: 2021Q3 | B29: 2021T3 | C29: 40.882759 | F29: -0.54581818 | I29: 208.12883
A30: 2021Q4 | B30: 2021T4 | C30: 59.304426 | F30: -0.56637656 | I30: 223.83696
... A37: 2023Q3 | B37: 2023T3 | C37: 42.346609 | F37: 3.7773872 | I37: 204.97402
A38: 2023Q4 | B38: 2023T4 | C38: 44.994272 | E38: 44.994272 | F38: 3.957456 | H38: 3.9574559 | I38: 206.60089 | K38: 206.60089
A39: 2024Q1 | B39: 2024T1 | C39: 39.674179 | D39: 39.674179 | E39: 39.587113 | F39: 3.9233789 | G39: 3.9233789 | H39: 3.8882558 | I39: 213.7639 | J39: 213.7639 | K39: 210.39182
A40: 2024Q2 | B40: 2024T2 | D40: 41.24095 | E40: 38.587038 | G40: 3.7860828 | H40: 3.6533334 | J40: 244.38704 | K40: 213.19501
A41: 2024Q3 | B41: 2024T3 | D41: 40.404486 | E41: 38.325443 | G41: 3.5433333 | H41: 3.2650001 | J41: 244.87525 | K41: 215.02333
A42: 2024Q4 | B42: 2024T4 | D42: 41.124661 | E42: 38.972014 | G42: 3.3 | H42: 2.905 | J42: 245.63615 | K42: 216.0122
A43: 2025Q1 | B43: 2025T1 | D43: 41.293964 | E43: 39.156598 | G43: 3.0716667 | H43: 2.635 | J43: 246.32097 | K43: 217.16582
A44: 2025Q2 | B44: 2025T2 | D44: 40.014927 | E44: 37.594223 | G44: 2.8833333 | H44: 2.4583333 | J44: 246.98356 | K44: 218.14476
A45: 2025Q3 | B45: 2025T3 | D45: 39.589631 | E45: 37.228874 | G45: 2.735 | H45: 2.3633332 | J45: 247.13657 | K45: 218.62221
A46: 2025Q4 | B46: 2025T4 | D46: 39.72359 | E46: 37.554342 | G46: 2.6233333 | H46: 2.3266666 | J46: 246.96319 | K46: 218.61891
A47: 2026Q1 | B47: 2026T1 | D47: 39.484 | E47: 37.50952 | G47: 2.5466667 | H47: 2.3266666 | J47: 248.3282 | K47: 219.21739
A48: 2026Q2 | B48: 2026T2 | D48: 36.425942 | E48: 35.684802 | G48: 2.4916667 | H48: 2.3399999 | J48: 249.76848 | K48: 219.38578
A49: 2026Q3 | B49: 2026T3 | D49: 35.856528 | E49: 35.289878 | G49: 2.455 | H49: 2.3616667 | J49: 249.52932 | K49: 218.26943
A50: 2026Q4 | B50: 2026T4 | D50: 36.308355 | E50: 35.69152 | G50: 2.4283333 | H50: 2.3833334 | J50: 248.5453 | K50: 216.28695
A53: Fontes: Eurosistema e Refinitiv (cálculos do Banco de Portugal).| Notas: As linhas a tracejado englobam o período posterior ao último trimestre completo aquando da data de fecho das hipóteses técnicas do exercício de projeção. As hipóteses técnicas para o preço do petróleo, do gás e das outras matérias-primas assentam nos mercados de futuros. O indicador sintético do preço da energia é uma média ponderada dos preços do petróleo e gás, ambos expressos em EUR/MWh (com ponderadores para Portugal baseados nas importações líquidas respetivas).
A54: Sources: Eurosystem and Refinitiv (Banco de Portugal calculations)| Notes: The dashed lines encompass the period after the last complete quarter at the closing date of the technical assumptions of the projection exercise. Technical assumptions for the price of oil, gas and other raw materials are based on futures markets. The synthetic energy price indicator is a weighted average of oil and gas prices, both expressed in EUR/MWh (with weights for Portugal based on the respective net imports).

Sheet QC.1.1
A5: Índice/Contents
A6: Boletim Económico - junho 2024/Economic Bulletin - June 2024
A7: =+Índice!$A$25 -> Caixa 1- Enquadramento e políticas/Box 1-External environment, financing conditions and policies
A10: Quadro C1.1 • Hipóteses do exercício de projeção elaboradas por especialistas do Eurosistema
A11: Table B1.1 • Eurosystem staff projection assumptions
C13: Unidade | D13: Unit | E13: BE junho 2024 | H13: 0 | I13: Revisões face ao BE março 2024 | L13: 0
E14: EB june 2024 | H14: 0 | I14: Revisions from EB march 2024 | L14: 0
E15: 2023 | F15: 2024 | G15: 2025 | H15: 2026 | I15: 2023 | J15: 2024 | K15: 2025 | L15: 2026
A17: Enquadramento internacional | B17: International environment
A18: PIB mundial | B18: World GDP | C18: tva | D18: yoy | E18: 3.1256537 | F18: 3.0287717 | G18: 3.0497791 | H18: 3.0264887 | I18: 0.012372409 | J18: -0.0018379022 | K18: 0.011736794 | L18: -0.01079721
A19: PIB Área do euro | B19: Euro area GDP | C19: tva | D19: yoy | E19: 0.6 | F19: 0.9 | G19: 1.4 | H19: 1.6 | I19: 0.1 | J19: 0.3 | K19: -0.1 | L19: 0
A20: Comércio mundial | B20: World trade | C20: tva | D20: yoy | E20: 0.42176308 | F20: 2.1087043 | G20: 3.2602987 | H20: 3.2444834 | I20: -0.13572421 | J20: -0.2171852 | K20: 0.12956244 | L20: 0.011620999
A21: Procura externa | B21: External demand | C21: tva | D21: yoy | E21: -0.50294917 | F21: 1.1456917 | G21: 3.1877117 | H21: 3.2420058 | I21: -0.041222018 | J21: -0.36993393 | K21: 0.10085887 | L21: 0.088708076
A23: Preços internacionais | B23: International prices
A24: Preço do petróleo | B24: Oil prices | C24: vma | D24: aav | E24: 77.451136 | F24: 77.655042 | G24: 72.43214 | H24: 69.159677 | I24: -1.358346e-08 | J24: 3.9057143 | K24: 3.0998379 | L24: 2.3192418
A25: Preço do gás (MWh) | B25: Gas prices (MWh) | C25: vma | D25: aav | E25: 40.613095 | F25: 30.819706 | G25: 35.41265 | H25: 29.93865 | I25: 0 | J25: 0.83352532 | K25: 3.325775 | L25: 0.39695833
A26: Matérias-primas não energéticas | B26: Non-oil commodity prices | C26: tva | D26: yoy | E26: -14.529652 | F26: 11.693508 | G26: 4.0838508 | H26: 0.88788605 | I26: 2.3293694e-05 | J26: 11.072042 | K26: 1.9859244 | L26: 0.8182233
A27: Preço de importação dos concorrentes | B27: Competitors' import prices | C27: tva | D27: yoy | E27: -1.5580303 | F27: 0.81989546 | G27: 2.6404624 | H27: 2.345748 | I27: -0.23227639 | J27: -0.18616241 | K27: -0.0029001823 | L27: -0.069877414
A29: Condições monetárias e financeiras | B29: Monetary and financial conditions
A30: Taxa de juro de curto prazo (EURIBOR a 3 meses) | B30: Short-term interest rate (3-month EURIBOR) | C30: % | D30: % | E30: 3.4307381 | F30: 3.6381988 | G30: 2.8283333 | H30: 2.4804167 | I30: -6.2496405e-05 | J30: 0.21030143 | K30: 0.38250007 | L30: 0.12750001
A31: Taxa de juro implícita da dívida pública | B31: Implicit interest rate in public debt | C31: % | D31: % | E31: 2.1480831 | F31: 2.4484075 | G31: 2.5102048 | H31: 2.5600957 | I31: 0.031099205 | J31: 0.11306572 | K31: 0.15573787 | L31: 0.15847761
A32: Índice de taxa de câmbio efetiva | B32: Effective exchange rate index | C32: tva | D32: yoy | E32: 4.8827669 | F32: 1.8102117 | G32: 0.10293139 | H32: 0 | I32: 2.1411594e-08 | J32: 0.74442455 | K32: 0.13682444 | L32: 0
A33: Taxa de câmbio euro-dólar | B33: Euro-dollar exchange rate | C33: vma | D33: aav | E33: 1.0813067 | F33: 1.0785848 | G33: 1.07661 | H33: 1.07661 | I33: 1.8853985e-10 | J33: -0.0022587525 | K33: -0.00337 | L33: -0.00337
A35: Fontes: Banco de Portugal e Eurosistema (cálculos do Banco de Portugal). | Notas: tva – taxa de variação anual, % – em percentagem, vma – valor médio anual, MWh – megawatt-hora. As hipóteses técnicas e de enquadramento externo e as projeções para o PIB e inflação da área do euro coincidem com as do exercício de projeção do Eurosistema divulgado a 6 de junho (ver “Projeções macroeconómicas para a área do euro elaboradas por especialistas do Eurosistema”, junho de 2024), incluindo a informação disponível até 21 de maio. Os preços internacionais são medidos em euros. A hipótese técnica para o preço do petróleo, gás e matérias-primas não energéticas assenta nos mercados de futuros. O preço de importação dos concorrentes corresponde a uma média ponderada dos deflatores de exportação dos países dos quais Portugal importa, ponderada pelo peso relativo nas importações portuguesas (para mais informação, ver “Trade consistency in the context of the Eurosystem projection exercises: an overview”, ECB Ocasional Paper 108, março de 2010). A evolução da taxa EURIBOR a 3 meses tem por base as expetativas implícitas nos contratos de futuros. A taxa de juro implícita da dívida pública é calculada como o rácio entre a despesa em juros do ano e a média simples do stock da dívida no final do ano e no final do ano anterior. Um aumento da taxa de câmbio corresponde a uma apreciação. O índice de taxa de câmbio efetiva do euro é calculado face a um grupo de 42 países parceiros. A revisão da taxa de câmbio euro-dólar é apresentada em percentagem. A hipótese técnica para as taxas de câmbio bilaterais pressupõe a manutenção ao longo do horizonte de projeção dos níveis médios observados nas duas semanas anteriores à data de fecho da informação.
A36: Sources: Banco de Portugal and Eurosystem (Banco de Portugal calculations). | Notes: yoy – year-on-year rate of change, % – in percentage, aav – annual average value, MWh – megawatt-hour. Technical and external environment assumptions, as well as projections for euro area GDP and inflation, coincide with those in the ECB projection exercise released on June 6 (see "Eurosystem staff macroeconomic projections for the euro area", june 2024), which include information up to May 21. International prices are in euros. The technical assumptions for the price of oil, gas and non-energy commodities is based on futures markets. The import price of competitors corresponds to a weighted average of the export deflators of the countries from which Portugal imports, weighted by their share on total Portuguese imports (for more information, see "Trade consistency in the context of the Eurosystem projection exercises: an overview", ECB Occasional Paper 108, March 2010). The evolution of the 3-month EURIBOR is based on expectations implied in futures contracts. The implicit interest rate on public debt is computed as the ratio of interest expenditure for the year to the simple average of the stock of debt at the end of the same year and at the end of the preceding year. An increase in the exchange rate corresponds to an appreciation of the euro. The effective exchange rate of the euro is computed against 41 trading partner countries. The technical assumption for bilateral exchange rates assumes that the average levels observed in the 10 business days prior to the cut-off date are maintained over the projection horizon.

Sheet GC.2.1
A5: Índice/Contents
A6: Boletim Económico - junho 2024/Economic Bulletin - June 2024
A7: =+Índice!A31 -> Caixa 2-Termos de troca no comércio de bens /Box 2-Terms of trade in goods
A10: Gráfico C2.1 • Termos de troca | Índice 2015 = 100
A11: Chart B2.1 • Terms of trade | Index 2015 = 100
D13: Unidade/Unit
E14: 2015 | F14: =+E14+1 -> 2016 | G14: =+F14+1 -> 2017 | H14: =+G14+1 -> 2018 | I14: =+H14+1 -> 2019 | J14: =+I14+1 -> 2020 | K14: =+J14+1 -> 2021 | L14: =+K14+1 -> 2022 | M14: =+L14+1 -> 2023
B16: Total de bens | C16: Total of goods | D16: Índice 2015 = 100/Index 2015 = 100 | E16: 100 | F16: 100.54058 | G16: 99.7452 | H16: 99.345425 | I16: 99.802379 | J16: 101.64847 | K16: 100.34898 | L16: 95.022477 | M16: 97.284704
B17: Bens excluindo energéticos | C17: Goods excluding energy | D17: Índice 2015 = 100/Index 2015 = 100 | E17: 100 | F17: 99.940043 | G17: 99.800487 | H17: 100.53175 | I17: 100.86826 | J17: 101.4886 | K17: 102.69789 | L17: 101.94459 | M17: 102.32361
B19: Fonte: INE – Estatísticas de Comércio Internacional de Bens (cálculos do Banco de Portugal).
B20: Nota: Sobre a decomposição da variação dos termos de troca ver nota ao gráfico C2.3.
B22: Source: Statistics Portugal - Goods International Trade Statistics (Banco de Portugal calculations).
B23: Notes: Regarding the terms of trade variation clause, see note to chart B2.3.

Sheet GC.2.2
A5: Índice/Contents
A6: Boletim Económico - junho 2024/Economic Bulletin - June 2024
A7: =+Índice!A31 -> Caixa 2-Termos de troca no comércio de bens /Box 2-Terms of trade in goods
A10: Gráfico C2.2 • Variação dos termos de troca de bens – contributos da componente energética e não energética | Em pontos percentuais
A11: Chart B2.2 • Terms of trade in goods change – contributions of energy and non-energy | In percentage points
D13: Unidade/Unit | E13: 2016 | F13: 2017 | G13: 2018 | H13: 2019 | I13: 2020 | J13: 2021 | K13: 2022 | L13: 2023
B15: Variação dos termos de troca de bens (pp) | C15: Change on goods terms of trade | D15: pp | E15: 0.54057934 | F15: -0.79537926 | G15: -0.39977491 | H15: 0.45695355 | I15: 1.846091 | J15: -1.2994933 | K15: -5.3264992 | L15: 2.262227
B16: Energéticos | C16: Energy | D16: pp | E16: 0.67268875 | F16: -0.76362484 | G16: -1.1054527 | H16: 0.14473525 | I16: 1.3442266 | J16: -2.6344755 | K16: -5.3602214 | L16: 1.8327708
B17: Não energéticos | C17: Non-energy | D17: pp | E17: -0.13210941 | F17: -0.031754417 | G17: 0.70567782 | H17: 0.3122183 | I17: 0.50186434 | J17: 1.3349822 | K17: 0.033722163 | L17: 0.42945622
B19: Fonte: INE – Estatísticas de Comércio Internacional de Bens (cálculos do Banco de Portugal).
B20: Nota: Sobre a decomposição da variação dos termos de troca ver nota ao gráfico C2.3.
B22: Source: Statistics Portugal - Goods International Trade Statistics (Banco de Portugal calculations).
B23: Notes: Regarding the terms of trade breakdown, see note to chart B2.3.

Sheet GC.2.3
A5: Índice/Contents
A6: Boletim Económico - junho 2024/Economic Bulletin - June 2024
A7: =+Índice!A31 -> Caixa 2-Termos de troca no comércio de bens /Box 2-Terms of trade in goods
A10: Gráfico C2.3 • Variação de termos de troca de bens e contributos dos efeitos estrutura e preço relativo | Em pontos percentuais
A11: Chart B2.3 • Terms of trade in goods change and contributions of structure and relative price effects | In percentage points
F13: Unidade/Unit | H13: 2016 | I13: 2017 | J13: 2018 | K13: 2019 | L13: 2020 | M13: 2021 | N13: 2022 | O13: 2023
B15: Painel A - Total de bens | C15: Panel A - Total goods | D15: Termos de troca total de bens | E15: Goods Terms of trade | F15: % | H15: 0.54057934 | I15: -0.79537926 | J15: -0.39977491 | K15: 0.45695355 | L15: 1.846091 | M15: -1.2994933 | N15: -5.3264992 | O15: 2.262227
D16: Contributo do efeito estrutura | E16: Structural effect | F16: pp | H16: 0.70533731 | I16: -0.89356044 | J16: -0.59510516 | K16: 0.17140696 | L16: 1.182021 | M16: -2.3437472 | N16: -3.6745579 | O16: 1.9447287
D17: Contributo do efeito preço relativo | E17: Relative price effect | F17: pp | H17: -0.16475797 | I17: 0.098181178 | J17: 0.19533025 | K17: 0.28554659 | L17: 0.66406994 | M17: 1.0442539 | N17: -1.6519413 | O17: 0.31749835
B19: Painel B - Bens excluindo energéticos | C19: Panel B - Goods excluding energy | D19: Termos de troca excluindo bens energéticos | E19: Goods excluding energy terms of trade | F19: % | H19: -0.059956681 | I19: -0.13955639 | J19: 0.731262 | K19: 0.33651308 | L19: 0.62033665 | M19: 1.2092919 | N19: -0.75329908 | O19: 0.37901796
D20: Contributo do efeito estrutura | E20: Structural effect | F20: pp | H20: -0.14949632 | I20: -0.059385274 | J20: 0.21106423 | K20: 0.0066118018 | L20: -0.027251744 | M20: -0.40511837 | N20: -0.13962487 | O20: -0.18989652
D21: Contributo do efeito preço relativo | E21: Relative price effect | F21: ppp | H21: 0.089539636 | I21: -0.080171113 | J21: 0.52019778 | K21: 0.32990128 | L21: 0.64758839 | M21: 1.6144103 | N21: -0.61367422 | O21: 0.56891448
B23: Fonte: INE – Estatísticas de Comércio Internacional de Bens (cálculos do Banco de Portugal).
B24: Source: Statistics Portugal - Goods International Trade Statistics (Banco de Portugal calculations).
B26: Notas: A variação dos termos de troca pode ser decomposta na soma dos contributos dos diferentes tipos de produtos i da seguinte forma:
B28: Sendo tvaXi,t e wXi,t (tvaMi,t e wMi,t) a taxa de variação anual do preço e o peso nas exportações totais (importações) de cada componente i em t. O efeito estrutura mede o impacto sobre os termos de troca da especialização setorial da economia. O efeito preço relativo mede o efeito da evolução diferenciada dos preços de exportação e importação em cada setor. Para mais detalhes, ver Cardoso, F. e Esteves, P. (2008), “Globalização, alterações estruturais das exportações e termos de troca de Portugal”, Boletim Económico Primavera 2008, Banco de Portugal.
B30: Notes: The terms of trade change may be broken down into the sum of contributions of different types of products i in the following way:
B32: Being yrcXi,t and wXi,t (yrcMi,t and wMi,t) the annual rate of change of prices and the weight in total exports (imports) of each component i in t. The structural effect measures the impact on the terms of trade of the sectoral specialization of the economy. The relative price effect measures the effect of the different export and import price evolution within each sector. For further details, see Cardoso, F. and Esteves, P. (2008), “Globalisation, Structural Changes in Exports and the Portuguese Terms of Trade”, Economic Bulletin Spring 2008, Banco de Portugal.

Sheet QC.2.1
A5: Índice/Contents
A6: Boletim Económico - junho 2024/Economic Bulletin - June 2024
A7: =+Índice!A31 -> Caixa 2-Termos de troca no comércio de bens /Box 2-Terms of trade in goods
A10: Quadro C2.1 • Contributos dos grupos de produtos para a variação dos termos de troca de bens – 2023 vs. 2015 | Variação acumulada em percentagem e contributos em pp
A11: Table B2.1 • Groups of products' contribution to the terms of trade total variation – 2023 vs. 2015 | Cumulative growth as a percentage and contributions in pp
A13: Unidade/Unit | H13: % | I13: % | J13: % | K13: % | L13: % | M13: pp | N13: pp | O13: pp
J14: 2023 vs 2015
H15: Peso médio no período | J15: Crescimento acumulado | M15: Contributos
H16: Average weight | J16: Cumulative growth | M16: Contributions
H17: Exportações | I17: Importações | J17: Preço de exportação | K17: Preço de importação | L17: Termos de troca | M17: Efeito estrutura | N17: Efeito preço relativo | O17: Efeito total
H18: Exports | I18: Imports | J18: Export prices | K18: Import prices | L18: Terms of trade | M18: Structural effect | N18: Relative price effect | O18: Total effect
B19: Agric. silv. e pescas | E19: Agriculture, hunting and fishing | H19: 3.0953758 | I19: 5.7006411 | J19: 14.636668 | K19: 27.685051 | L19: -13.048383 | M19: -0.48504941 | N19: -0.59709603 | O19: -1.0821454
B20: Indústrias extrativas | E20: Mining and quarrying | H20: 1.1325866 | I20: 0.19787074 | J20: 35.768955 | K20: 11.577051 | L20: 24.191904 | M20: 0.18586517 | N20: 0.13133757 | O20: 0.31720274
B21: Bens manufaturados | E21: Manufacturing | H21: 89.370233 | I21: 82.128083 | J21: 21.614432 | K21: 18.568549 | L21: 3.0458827 | M21: 1.2678366 | N21: 2.6511633 | O21: 3.9189999
C22: Alimentares e bebidas | F22: Food and beverages | H22: 8.9117863 | I22: 9.4212126 | J22: 30.277196 | K22: 29.441917 | L22: 0.83527898 | M22: -0.1108243 | N22: 0.068526668 | O22: -0.042297636
C23: Artigos de borracha e de matérias plásticas | F23: Rubber and plastic produtes | H23: 5.562144 | I23: 3.2125036 | J23: 21.15375 | K23: 4.9617905 | L23: 16.191959 | M23: 0.25205078 | N23: 0.72786356 | O23: 0.97991434
C24: Setor têxtil e do calçado | F24: Textiles, clothing and footwear | H24: 11.92763 | I24: 6.9616623 | J24: 20.676468 | K24: 1.3872488 | L24: 19.289219 | M24: 0.47846038 | N24: 1.7881023 | O24: 2.2665627
D25: Têxteis | G25: Textiles | H25: 3.2651836 | I25: 2.2610582 | J25: 13.863734 | K25: -1.350479 | L25: 15.214213 | M25: 0.080592215 | N25: 0.39015047 | O25: 0.47074269
D26: Vestuário | G26: Clothing | H26: 5.6756905 | I26: 3.7713126 | J26: 28.081941 | K26: -1.2342332 | L26: 29.316174 | M26: 0.19413066 | N26: 1.389205 | O26: 1.5833356
D27: Calçado e produtos de couro | G27: Footwear and leather products | H27: 2.9867557 | I27: 0.92929157 | J27: 14.823015 | K27: 18.756064 | L27: -3.9330494 | M27: 0.31035696 | N27: -0.097872586 | O27: 0.21248438
C28: Madeira, cortiça e papel | F28: Wood, cork, pulp and paper products | H28: 7.211789 | I28: 2.817951 | J28: 31.246561 | K28: 18.899209 | L28: 12.347352 | M28: 1.0008026 | N28: 0.61169985 | O28: 1.6125024
C29: Máquinas e equipamentos | F29: Machinery and equipment | H29: 15.26764 | I29: 17.984798 | J29: 19.822895 | K29: 23.663392 | L29: -3.8404966 | M29: -0.35034299 | N29: -0.52160043 | O29: -0.87194342
C30: Material de transporte | F30: Transport equipment | H30: 13.994166 | I30: 13.715569 | J30: 18.608608 | K30: 16.881432 | L30: 1.727176 | M30: 0.11179791 | N30: 0.21902983 | O30: 0.33082774
C31: Minerais e produtos metálicos | F31: Mineral and metal products | H31: 12.261525 | I31: 9.2827235 | J31: 22.725915 | K31: 26.93186 | L31: -4.205945 | M31: 0.56919502 | N31: -0.44192194 | O31: 0.12727307
C32: Produtos químicos | F32: Chemical products | H32: 8.0810237 | I32: 14.423955 | J32: 24.838644 | K32: 16.662877 | L32: 8.175767 | M32: -1.6341351 | N32: 1.0087632 | O32: -0.62537187
C33: Outros | F33: Other | H33: 6.1525287 | I33: 4.3077073 | J33: 11.356308 | K33: 11.595532 | L33: -0.23922447 | M33: 0.18470514 | N33: -0.043172597 | O33: 0.14153255
B35: Bens não energéticos | E35: Non-energy | H35: 93.598195 | I35: 88.026595 | J35: 21.441273 | K35: 19.117663 | L35: 2.3236095 | M35: 0.30914466 | N35: 2.8449125 | O35: 3.1540572
B36: Bens energéticos | E36: Energy | H36: 6.4018048 | I36: 11.973405 | J36: 87.523518 | K36: 113.58995 | L36: -26.06643 | M36: -3.8126214 | N36: -2.0567316 | O36: -5.869353
B38: TOTAL | E38: TOTAL | H38: 100 | I38: 100 | J38: 22.873316 | K38: 25.588612 | L38: -2.7152958 | M38: -3.5034768 | N38: 0.78818095 | O38: -2.7152958
B40: Fonte: INE – Estatísticas de Comércio Internacional de Bens (cálculos do Banco de Portugal).
B41: Nota: Sobre a decomposição da variação dos termos de troca ver nota ao gráfico C2.3.
B43: Source: Statistics Portugal - Goods International Trade Statistics (Banco de Portugal calculations).
B44: Notes: Regarding the terms of trade breakdown, see note to Chart B2.3.

Sheet GC.3.1
A5: Índice/Contents
A6: Boletim Económico - junho 2024/Economic Bulletin - June 2024
A7: =+Índice!$A$41 -> Caixa 3 - A transmissão do preço dos bens energéticos ao IHPC / Box 3- The pass-through of energy prices to the HICP
A10: Gráfico C3.1 • IHPC total e IHPC de bens energéticos | Taxa de variação homóloga em percentagem e contributos em pontos percentuais
A11: Chart B3.1 • HICP headline and HICP of energy goods | Year-on-year change rate in percentage and contributions in percentage points
C13: Painel A – IHPC total | G13: Painel B – IHPC de bens energéticos
C14: Panel A – HICP headline | G14: Panel B – HICP of energy goods
A15: Unidade/Unit | C15: % | D15: pp | E15: pp | G15: % | H15: pp | I15: pp | J15: pp | K15: pp
C16: IHPC total (tvh, %) | D16: Energéticos | E16: Componente não energética | G16: Energéticos (%) | H16: Eletricidade | I16: Gás | J16: Gasóleo+ Gasolina | K16: Outros
C17: HICP headline (%) | D17: Energy | E17: Non-energy component | G17: Energy goods (%) | H17: Electricity | I17: Gas | J17: Diesel+ Gasoline | K17: Other
A18: 2021T1 | B18: 2021Q1 | C18: 0.19465983 | D18: -0.1181629 | E18: 0.30414705 | G18: -1.7781758 | H18: -0.36087318 | I18: -0.63396667 | J18: -0.65117341 | K18: -0.070778714
A19: 2021T2 | B19: 2021Q2 | C19: -0.060478737 | D19: 0.67556556 | E19: -0.73896652 | G19: 9.3519193 | H19: -0.092023851 | I19: 0.06806711 | J19: 9.0539382 | K19: 0.32209581
A20: 2021T3 | B20: 2021Q3 | C20: 1.2273694 | D20: 0.75768955 | E20: 0.4706718 | G20: 9.7944581 | H20: 0.63973293 | I20: 0.33260398 | J20: 8.4850842 | K20: 0.33788125
A21: 2021T4 | B21: 2021Q4 | C21: 2.411814 | D21: 1.0236634 | E21: 1.3878774 | G21: 13.236637 | H21: 1.0528085 | I21: 1.1214061 | J21: 10.527432 | K21: 0.54578825
A22: 2022T1 | B22: 2022Q1 | C22: 4.4199074 | D22: 1.2587494 | E22: 3.1578129 | G22: 15.941651 | H22: 2.0482422 | I22: 1.8307119 | J22: 11.425264 | K22: 0.60913749
A23: 2022T2 | B23: 2022Q2 | C23: 8.1663853 | D23: 2.2522634 | E23: 5.9172338 | G23: 28.88445 | H23: 7.6590392 | I23: 4.3853504 | J23: 15.822469 | K23: 0.99920766
A24: 2022T3 | B24: 2022Q3 | C24: 9.5312351 | D24: 2.0647473 | E24: 7.4614111 | G24: 25.889152 | H24: 11.490878 | I24: 3.7003622 | J24: 9.7866459 | K24: 0.92787996
A25: 2022T4 | B25: 2022Q4 | C25: 10.207166 | D25: 1.9626659 | E25: 8.2433214 | G25: 24.331184 | H25: 9.5804664 | I25: 8.9746688 | J25: 5.1436658 | K25: 0.63420505
A26: 2023T1 | B26: 2023Q1 | C26: 8.394319 | D26: 0.19234509 | E26: 8.1952695 | G26: 1.3985621 | H26: -1.8124827 | I26: 6.6876946 | J26: -3.5180692 | K26: 0.22065746
A27: 2023T2 | B27: 2023Q2 | C27: 5.6535438 | D27: -1.3342156 | E27: 6.977075 | G27: -15.775618 | H27: -6.6893257 | I27: 1.7022828 | J27: -10.385326 | K27: -0.33828269
A28: 2023T3 | B28: 2023Q3 | C28: 4.8143413 | D28: -0.73525871 | E28: 5.5366335 | G28: -8.4951041 | H28: -6.4598752 | I28: 1.5460972 | J28: -3.2470055 | K28: -0.20252416
A29: 2023T4 | B29: 2023Q4 | C29: 2.4454348 | D29: -0.98114581 | E29: 3.4247086 | G29: -11.42864 | H29: -5.6657818 | I29: -3.9073115 | J29: -1.7668884 | K29: -0.073541413
A30: 2024T1 | B30: 2024Q1 | C30: 2.4631669 | D30: 0.17500238 | E30: 2.2839654 | G30: 3.0133496 | H30: 5.431499 | I30: -3.3682944 | J30: 0.9322441 | K30: 0.043773707
A32: Fonte: Eurostat (cálculos do Banco de Portugal).
A33: Source: Eurostat (Banco de Portugal calculations).

Sheet GC.3.2
A5: Índice/Contents
A6: Boletim Económico - junho 2024/Economic Bulletin - June 2024
A7: =+Índice!$A$41 -> Caixa 3 - A transmissão do preço dos bens energéticos ao IHPC / Box 3- The pass-through of energy prices to the HICP
A10: Gráfico C3.2 • Resposta da inflação e dos seus componentes a um choque de 1 desvio padrão no preço dos bens energéticos | Pontos percentuais
A11: Chart B3.2 • Response of inflation and its components to a shock of 1 standard deviation in energy prices | Percentage points
A13: unidade/unit: pp | C13: meses após o choque
C14: months after shock
C15: t | D15: t +6 | E15: t +12 | F15: t +18 | G15: t +24
A16: IHPC total | B16: HICP headline | C16: 0.2141088 | D16: 0.2359512 | E16: 0.18714926 | F16: 0.095243145 | G16: 0.01788294
A17: IHPC subjacente | B17: HICP core | C17: 0.0076224203 | D17: 0.049846428 | E17: 0.061007224 | F17: 0.040515612 | G17: 0.011421839
A18: IHPC alimentares | B18: HICP food | C18: 0.026486205 | D18: 0.081709921 | E18: 0.084860231 | F18: 0.051328225 | G18: 0.015299722
A19: IHPC energia | B19: HICP energy | C19: 0.18000017 | D19: 0.10439485 | E19: 0.041281804 | F19: 0.0033993078 | G19: -0.0088386212
