Workbook
Name \a: #REF!
Name \b: #REF!
Name \C: #REF!
Name \D: #REF!
Name \E: #REF!
Name \F: #REF!
Name \I: #REF!
Name \J: #REF!
Name \O: #REF!
Name \P: #REF!
Name \Q: #REF!
Name \R: #REF!
Name \S: #REF!
Name \T: #REF!
Name \X: #REF!
Name \Z: #REF!
Name __: #REF!
Name ________: #REF!
Name __________ssmdndkdsldsjsld: #REF!
Name ___bot1: #REF!
Name ___bot2: #REF!
Name ___bot3: #REF!
Name ___bot4: #REF!
Name ___bot5: #REF!
Name ___bot6: #REF!
Name ___top1: #REF!
Name ___top2: #REF!
Name ___top3: #REF!
Name ___top4: #REF!
Name ___top5: #REF!
Name ___top6: #REF!
Name __ano1990: #REF!
Name __bot1: #REF!
Name __bot2: #REF!
Name __bot3: #REF!
Name __bot4: #REF!
Name __bot5: #REF!
Name __bot6: #REF!
Name __EXP10: #REF!
Name __EXP30: #REF!
Name __EXP5: #REF!
Name __OI10: #REF!
Name __OI30: #REF!
Name __Ois1: #REF!
Name __OIS2: #REF!
Name __OIS3: #REF!
Name __top1: #REF!
Name __top2: #REF!
Name __top3: #REF!
Name __top4: #REF!
Name __top5: #REF!
Name __top6: #REF!
Name _ano1990: #REF!
Name _bot1: #REF!
Name _bot2: #REF!
Name _bot3: #REF!
Name _bot4: #REF!
Name _bot5: #REF!
Name _bot6: #REF!
Name _DI_NACE: #REF!

Sheet Capa
A1: s
A48: Nota: Neste ficheiro são disponiblizados os dados subjacentes aos gráficos e quadros do Boletim Económico – março 2024.
A49: Note: This file contains the data used in the charts and tables of the Economic Bulletin – March 2024.

Sheet Índice
B1: Classificação de Segurança - Público
A5: Boletim Económico - março 2024 / Economic Bulletin - March 2024
A6: ÍNDICE/CONTENTS
A7: Parte I. Projeções para a economia portuguesa: 2024-26 / Part I. Projections for the Portuguese economy: 2024-26
A8: =HYPERLINK("#"&C8,INDIRECT(C8)) -> Quadro I.1.1 • Projeções do Banco de Portugal para 2024-26 | Taxa de variação anual em percentagem (exceto onde indicado) | C8: QI.1.1!A$10
A9: =HYPERLINK("#"&C9,INDIRECT(C9)) -> Table I.1.1 • Projections of Banco de Portugal for 2024-26| Annual rate of change in percentage (unless otherwise stated) | C9: QI.1.1!A$11
A10: =HYPERLINK("#"&C10,INDIRECT(C10)) -> Gráfico I.1.1 • Projeções trimestrais para o PIB e para a inflação | C10: GI.1.1!A$10
A11: =HYPERLINK("#"&C11,INDIRECT(C11)) -> Chart I.1.1 • Quarterly projections for GDP and inflation | C11: GI.1.1!A$11
A12: =HYPERLINK("#"&C12,INDIRECT(C12)) -> Gráfico I.1.2 • IHPC, deflator das importações e deflator do PIB - Taxa de variação anual | Percentagem | C12: GI.1.2!A$10
A13: =HYPERLINK("#"&C13,INDIRECT(C13)) -> Chart I.1.2 • HICP, imports deflator and GDP deflator - Annual rate of change | Percentage | C13: GI.1.2!A$11
A14: =HYPERLINK("#"&C14,INDIRECT(C14)) -> Gráfico I.1.3 • Decomposição da taxa de variação do deflator do PIB na ótica do rendimento | Percentagem e pp | C14: GI.1.3!A$10
A15: =HYPERLINK("#"&C15,INDIRECT(C15)) -> Chart I.1.3 • Decomposition of GDP deflator rate of change (income side) | Percentage and percentage points | C15: GI.1.3!A$11
A16: =HYPERLINK("#"&C16,INDIRECT(C16)) -> Gráfico I.1.4 • PIB e agregados da despesa em Portugal e na área do euro – taxa de variação média 2024-26| Em percentagem | C16: GI.1.4!A$10
A17: =HYPERLINK("#"&C17,INDIRECT(C17)) -> Chart I.1.4 • GDP and expenditure side aggregates in Portugal and the euro area – average rate of change 2024-26 | Percentage | C17: GI.1.4!A$11
A18: =HYPERLINK("#"&C18,INDIRECT(C18)) -> Gráfico I.1.5 • Endividamento dos particulares, empresas não financeiras e administrações públicas em Portugal e na área do euro | Em percentagem do PIB | C18: GI.1.5!A$10
A19: =HYPERLINK("#"&C19,INDIRECT(C19)) -> Chart I.1.5 • Debt of households, non-financial corporations and public administrations in Portugal and the euro area | Percentage of GDP | C19: GI.1.5!A$11
... A27: =HYPERLINK("#"&C27,INDIRECT(C27)) -> Chart I.1.9 • Change in jobs between 2019 and 2023 and average monthly wages in 2023 - by technological and knowledge intensity | Thousands and euros | C27: GI.1.9!A$11
A29: Caixa 1- Enquadramento e políticas / Box 1-External environment, financing conditions and policies
A30: =HYPERLINK("#"&C30,INDIRECT(C30)) -> Quadro C1.1 • Hipóteses do exercício de projeção | C30: QC1.1!A$10
A31: =HYPERLINK("#"&C31,INDIRECT(C31)) -> Table C1.1 • Eurosystem staff projection assumptions | C31: QC1.1!A$11
A32: =HYPERLINK("#"&C32,INDIRECT(C32)) -> Gráfico C1.1 • PIB da área do euro e maiores países | Taxa de variação anual | C32: GC1.1!A$10
A33: =HYPERLINK("#"&C33,INDIRECT(C33)) -> Chart C1.1 • Euro area and major countries GDP | Annual rate of change | C33: GC1.1!A$11
A35: Caixa 2 - Expetativas de taxas de juro e de consumo das famílias / Box 2 - Consumers' expectations on interest rates and consumption
A36: =HYPERLINK("#"&C36,INDIRECT(C36)) -> Quadro C2.1 • Características dos consumidores inquiridos | Valores médios e percentagem | C36: QC2.1!A$10
A37: =HYPERLINK("#"&C37,INDIRECT(C37)) -> Table C2.1 • Characteristics of the surveyed consumers | Mean values and percentage | C37: QC2.1!A$11
A38: =HYPERLINK("#"&C38,INDIRECT(C38)) -> Gráfico C2.1 • Situação financeira dos consumidores em Portugal total e por situação de crédito | Saldo de respostas extremas | C38: GC2.1!A$10
A39: =HYPERLINK("#"&C39,INDIRECT(C39)) -> Chart C2.1 • Consumers' financial situation in Portugal in total and by housing type | Net percentage | C39: GC2.1!A$11
A40: =HYPERLINK("#"&C40,INDIRECT(C40)) -> Gráfico C2.2 • Impacto do aumento de 1 pp nas expetativas de taxas de juro sobre as expetativas de consumo nos 12 meses seguintes | Pontos percentuais | C40: GC2.2!A$10
A41: =HYPERLINK("#"&C41,INDIRECT(C41)) -> Chart C2.2 • Impact of an increase of 1 pp of expectatations for interest rates on spending expectations in the next 12 months | Percentage points | C41: GC2.2!A$11
A43: Caixa 3 - Evolução dos empréstimos às empresas na sequência das medidas de apoio ao crédito na pandemia / Box 3 - Evolution of corporate loans following the credit support measures during the pandemic
A44: =HYPERLINK("#"&C44,INDIRECT(C44)) -> Quadro C3.1 • Características das empresas dos grupos analisados em 2019 | Valores médios | C44: QC3.1!A$10
A45: =HYPERLINK("#"&C45,INDIRECT(C45)) -> Table C3.1 • Firm Characteristics by group in 2019 | Mean values | C45: QC3.1!A$11
A46: =HYPERLINK("#"&C46,INDIRECT(C46)) -> Gráfico C3.1 • Empréstimos a sociedades não financeiras – Decomposição dos fluxos líquidos mensais | Soma dos últimos três meses, milhões de euros | C46: GC3.1!A$10
A47: =HYPERLINK("#"&C47,INDIRECT(C47)) -> Chart C3.1 • Loans to non-financial corporations – Breakdown of monthly net flows | Sum of the last three months, millions of euros | C47: GC3.1!A$11
A48: =HYPERLINK("#"&C48,INDIRECT(C48)) -> Gráfico C3.2 • Decomposição dos fluxos líquidos mensais dos empréstimos| Soma dos últimos três meses, em milhões de euros | C48: GC3.2!A$10
A49: =HYPERLINK("#"&C49,INDIRECT(C49)) -> Chart C3.2 • Breakdown of monthly net loan flows | Sum of the last three months, in millions of euros | C49: GC3.2!A$11
A50: =HYPERLINK("#"&C50,INDIRECT(C50)) -> Gráfico C3.3 • Decomposição dos fluxos líquidos mensais dos empréstimos: Empresas elegíveis sem crédito com garantia pública e sem moratória | Soma dos últimos três meses, em milhões de euros | C50: GC3.3!A$10
A51: =HYPERLINK("#"&C51,INDIRECT(C51)) -> Chart C3.3 • Breakdown of monthly net loan flows: Eligible firms without public guaranteed credit and without moratorium | Sum of the last three months, in millions of euros | C51: GC3.3!A$11
A52: =HYPERLINK("#"&C52,INDIRECT(C52)) -> Gráfico C3.4 • Empréstimos a sociedades não financeiras – Decomposição dos fluxos líquidos mensais | Soma dos últimos três meses, milhões de euros | C52: GC3.4!A$10
A53: =HYPERLINK("#"&C53,INDIRECT(C53)) -> Chart C3.4 • Loans to non-financial corporations – Breakdown of monthly net flows | Sum of the last three months, millions of euros | C53: GC3.4!A$11
...

Sheet QI.1.1
A5: Índice/Contents
A6: =+Índice!$A$5 -> Boletim Económico - março 2024 / Economic Bulletin - March 2024
A7: =+Índice!$A$7 -> Parte I. Projeções para a economia portuguesa: 2024-26 / Part I. Projections for the Portuguese economy: 2024-26
A10: Quadro I.1.1 • Projeções do Banco de Portugal para 2024-26 | Taxa de variação anual em percentagem (exceto onde indicado)
A11: Table I.1.1 • Projections of Banco de Portugal for 2024-26| Annual rate of change in percentage (unless otherwise stated)
A13: Unidade/Unit | C13: % | E13: % | F13: % | G13: % | H13: % | J13: % | K13: % | L13: % | M13: %
C14: Pesos | E14: BE março 2024 | J14: BE dezembro 2023
C15: Weights | E15: EB March 2024 | J15: EB December 2023
C16: 2023 | E16: 2023 | F16: 2024 (p) | G16: 2025 (p) | H16: 2026 (p) | J16: 2023 (p) | K16: 2024 (p) | L16: 2025 (p) | M16: 2026 (p)
A18: Produto interno bruto | B18: Gross domestic product | C18: 100 | E18: 2.28052 | F18: 2.0459739 | G18: 2.2967685 | H18: 2.2083861 | J18: 2.1064862 | K18: 1.2181047 | L18: 2.1663045 | M18: 2.0093188
A20: Consumo privado | B20: Private consumption | C20: 62.500411 | E20: 1.6336574 | F20: 2.0820899 | G20: 1.925106 | H20: 1.826615 | J20: 0.97115535 | K20: 1.0098223 | L20: 1.7062625 | M20: 1.5234711
A21: Consumo público | B21: Public consumption | C21: 17.093261 | E21: 1.2415149 | F21: 1.1926705 | G21: 0.877828 | H21: 0.92772281 | J21: 1.0823475 | K21: 1.0157233 | L21: 0.85860336 | M21: 0.89481758
A22: Formação bruta de capital fixo | B22: Gross fixed capital formation | C22: 19.351306 | E22: 2.4401542 | F22: 3.6218192 | G22: 5.4391424 | H22: 4.119236 | J22: 0.88737301 | K22: 2.4420366 | L22: 5.2029813 | M22: 4.0580137
A23: Procura interna | B23: Domestic demand | C23: 99.137515 | E23: 1.4102447 | F23: 2.3656595 | G23: 2.4059002 | H23: 2.1184762 | J23: 0.74604004 | K23: 1.3910888 | L23: 2.2102242 | M23: 1.900546
A24: Exportações | B24: Exports | C24: 47.429847 | E24: 4.1830157 | F24: 3.5118923 | G24: 4.0090788 | H24: 3.2996928 | J24: 4.3270104 | K24: 2.4349847 | L24: 3.969907 | M24: 2.9953467
A25: Importações | B25: Imports | C25: 46.567361 | E25: 2.2315081 | F25: 4.2144287 | G25: 4.2560516 | H25: 3.1101558 | J25: 1.3022178 | K25: 2.7937696 | L25: 4.0979024 | M25: 2.7792001
A27: Emprego (a) | B27: Employment (a) | E27: 0.8631955 | F27: 0.69846792 | G27: 0.58508385 | H27: 0.45415575 | J27: 0.82568162 | K27: 0.12659846 | L27: 0.34132223 | M27: 0.32691028
A28: Taxa de desemprego (b) | B28: Unemployment rate (b) | E28: 6.5091485 | F28: 6.5148295 | G28: 6.4592335 | H28: 6.4636811 | J28: 6.5494816 | K28: 7.0574451 | L28: 7.2950097 | M28: 7.1504139
A30: Balança corrente e de capital (% PIB) | B30: Current and capital account (% of GDP) | E30: 2.7255972 | F30: 3.595957 | G30: 3.8835519 | H30: 4.08046 | J30: 3.0458346 | K30: 3.4560927 | L30: 3.71566 | M30: 4.0260773
A31: Balança de bens e serviços (% PIB) | B31: Trade balance (% of GDP) | E31: 1.2327243 | F31: 1.1249379 | G31: 1.2303927 | H31: 1.4790873 | J31: 1.1704602 | K31: 1.3318268 | L31: 1.4852096 | M31: 1.7574905
A33: Índice harmonizado de preços no consumidor | B33: Harmonised index of consumer prices | E33: 5.2642832 | F33: 2.3577992 | G33: 1.9997807 | H33: 1.9371263 | J33: 5.307806 | K33: 2.9234759 | L33: 1.9742583 | M33: 1.9632434
A34: Bens energéticos | B34: Energy | E34: -8.9092019 | F34: 3.6141984 | G34: 2.1580193 | H34: 0.58776934 | J34: -8.7558142 | K34: 3.4777526 | L34: 0.21741877 | M34: -0.13480671
A35: Bens alimentares | B35: Food | E35: 9.2039871 | F35: 3.0211879 | G35: 1.2980433 | H35: 1.5 | J35: 9.1615556 | K35: 4.4084926 | L35: 2.1626541 | M35: 2.1
A36: Excluindo bens energéticos | B36: Excluding energy | E36: 6.5476591 | F36: 2.2791734 | G36: 1.9902956 | H36: 2.022027 | J36: 6.5803952 | K36: 2.8786934 | L36: 2.1093382 | M36: 2.1215695
A37: Excluindo bens energéticos e alimentares | B37: Excluding energy and food | E37: 5.3698003 | F37: 2.0207849 | G37: 2.2275851 | H37: 2.1964871 | J37: 5.4270985 | K37: 2.3385621 | L37: 2.0903421 | M37: 2.1115218
A39: Fontes: Banco de Portugal e INE. | Notas: (p) – projetado. O fecho de dados do exercício de projeção ocorreu a 12 de março. A projeção corresponde ao valor mais provável condicional ao conjunto de hipóteses consideradas. Pesos de 2023 a preços correntes. (a) De acordo com o conceito de Contas Nacionais. (b) Em percentagem da população ativa.
A40: Sources: Banco de Portugal and Statistics Portugal. | Notes: (p) - projected. Cut-off date for macroeconomic projections: March 12. The projection corresponds to the most likely value conditional on the set of hypotheses considered. 2023 weights at current prices. (a) According to the National Accounts concept. (b) As a percentage of the labour force.

Sheet GI.1.1
A5: Índice/Contents
A6: =+Índice!$A$5 -> Boletim Económico - março 2024 / Economic Bulletin - March 2024
A7: =+Índice!$A$7 -> Parte I. Projeções para a economia portuguesa: 2024-26 / Part I. Projections for the Portuguese economy: 2024-26
A10: Gráfico I.1.1 • Projeções trimestrais para o PIB e para a inflação
A11: Chart I.1.1 • Quarterly projections for GDP and inflation
A13: Unidade/Unit | C13: % | D13: % | E13: % | F13: % | G13: % | H13: % | I13: % | J13: % | K13: % | L13: % | M13: % | N13: % | O13: % | P13: % | Q13: % | R13: %
C14: 2023 | G14: 2024 | K14: 2025 | O14: 2026
C15: T1 | D15: T2 | E15: T3 | F15: T4 | G15: T1 | H15: T2 | I15: T3 | J15: T4 | K15: T1 | L15: T2 | M15: T3 | N15: T4 | O15: T1 | P15: T2 | Q15: T3 | R15: T4
C16: Q1 | D16: Q2 | E16: Q3 | F16: Q4 | G16: Q1 | H16: Q2 | I16: Q3 | J16: Q4 | K16: Q1 | L16: Q2 | M16: Q3 | N16: Q4 | O16: Q1 | P16: Q2 | Q16: Q3 | R16: Q4
A18: Painel A – PIB - taxa de variação em cadeia | Percentagem | B18: Panel A – GDP - quarter-on-quarter growth rate | Percentage
A19: BE de março 2024 | B19: EB March 2024 | C19: 1.460228 | D19: 0.087780531 | E19: -0.19607811 | F19: 0.79644871 | G19: 0.66983929 | H19: 0.55876798 | I19: 0.56552396 | J19: 0.55192475 | K19: 0.59769204 | L19: 0.58541301 | M19: 0.56310902 | N19: 0.49053571 | O19: 0.52966022 | P19: 0.58876109 | Q19: 0.57612743 | R19: 0.54041728
A20: BE de dezembro 2023 | B20: EB December 2023 | C20: 1.4658033 | D20: 0.07 | E20: -0.19152501 | F20: 0.13618401 | G20: 0.32765093 | H20: 0.51440007 | I20: 0.63396056 | J20: 0.62972357 | K20: 0.5339378 | L20: 0.45148494 | M20: 0.46489295 | N20: 0.50790859 | O20: 0.46618294 | P20: 0.54435163 | Q20: 0.52799978 | R20: 0.51732294
A23: Painel B – IHPC - taxa de variação em cadeia | Percentagem | B23: Panel B – HICP - quarter-on-quarter growth rate | Percentage
A24: BE de março 2024 | B24: EB March 2024 | C24: 8.394319 | D24: 5.6535438 | E24: 4.8143413 | F24: 2.4454348 | G24: 2.3345525 | H24: 2.6090358 | I24: 2.2353349 | J24: 2.2522741 | K24: 1.9240392 | L24: 1.8929787 | M24: 2.0596441 | N24: 2.1206954 | O24: 2.0855065 | P24: 1.9645688 | Q24: 1.8761986 | R24: 1.8264064
A25: BE de dezembro 2023 | B25: EB December 2023 | C25: 8.394319 | D25: 5.6535438 | E25: 4.8143413 | F25: 2.6140738 | G25: 2.9430326 | H25: 3.1911721 | I25: 2.790058 | J25: 2.7710286 | K25: 1.9763091 | L25: 1.8486801 | M25: 2.0081865 | N25: 2.0641355 | O25: 2.0264003 | P25: 1.9571619 | Q25: 1.9165498 | R25: 1.9546981
A28: Fontes: Banco de Portugal e INE. | Nota: As linhas a tracejado correspondem aos valores projetados nos BE de dezembro de 2023 e março de 2024.
A29: Sources: Banco de Portugal and Statistics Portugal. | Note: The dashed lines correspond to the projected values in the EB of December 2023 and March 2024.

Sheet GI.1.2
A5: Índice/Contents
A6: =+Índice!$A$5 -> Boletim Económico - março 2024 / Economic Bulletin - March 2024
A7: =+Índice!$A$7 -> Parte I. Projeções para a economia portuguesa: 2024-26 / Part I. Projections for the Portuguese economy: 2024-26
A10: Gráfico I.1.2 • IHPC, deflator das importações e deflator do PIB - Taxa de variação anual | Percentagem
A11: Chart I.1.2 • HICP, imports deflator and GDP deflator - Annual rate of change | Percentage
A13: Unidade/Unit | C13: % | D13: % | E13: % | F13: % | G13: % | H13: % | I13: % | J13: %
C14: 2019 | D14: 2020 | E14: 2021 | F14: 2022 | G14: 2023 | H14: 2024 (p) | I14: 2025 (p) | J14: 2026 (p)
A16: IHPC | B16: HICP | C16: 0.29982107 | D16: -0.12133777 | E16: 0.94130898 | F16: 8.1026581 | G16: 5.2642832 | H16: 2.3577992 | I16: 1.9997807 | J16: 1.9371263
A17: Deflator do PIB | B17: GDP deflator | C17: 1.7494519 | D17: 2.003475 | E17: 1.9005944 | F17: 4.9984106 | G17: 7.2113015 | H17: 3.1631487 | I17: 2.5503928 | J17: 2.4030174
A18: Deflator das importações | B18: Imports deflator | C18: -0.2719493 | D18: -3.4588542 | E18: 8.3224915 | F18: 18.772999 | G18: -3.9548596 | H18: -0.3039723 | I18: 1.892491 | J18: 1.8833207
A20: Fontes: Banco de Portugal e INE. | Notas: (p) – projetado.
A21: Sources: Banco de Portugal and Statistics Portugal. | Notes: (p) - projected.

Sheet GI.1.3
A5: Índice/Contents
A6: =+Índice!$A$5 -> Boletim Económico - março 2024 / Economic Bulletin - March 2024
A7: =+Índice!$A$7 -> Parte I. Projeções para a economia portuguesa: 2024-26 / Part I. Projections for the Portuguese economy: 2024-26
A10: Gráfico I.1.3 • Decomposição da taxa de variação do deflator do PIB na ótica do rendimento | Percentagem e pp
A11: Chart I.1.3 • Decomposition of GDP deflator rate of change (income side) | Percentage and percentage points
C13: Unidade/Unit | F13: 2019 | G13: 2020 | H13: 2021 | I13: 2022 | J13: 2023 | K13: 2024 (p) | L13: 2025 (p) | M13: 2026 (p)
A15: Deflator do PIB | B15: GDP deflator | C15: % | F15: 1.7494519 | G15: 2.003475 | H15: 1.9005944 | I15: 4.9984106 | J15: 7.2113015 | K15: 3.1631487 | L15: 2.5503928 | M15: 2.4030174
A16: Custos unitários do trabalho | B16: Unit labour costs | C16: pp | F16: 1.6889966 | G16: 4.2260436 | H16: 0.82875743 | I16: 0.46199847 | J16: 3.5153165 | K16: 1.5773966 | L16: 1.0420234 | M16: 1.0165858
A17: Excedente bruto de exploração | B17: Gross operating surplus | C17: pp | F17: -0.11825524 | G17: -1.8696562 | H17: 0.24418441 | I17: 3.7917704 | J17: 3.33875 | K17: 0.87070908 | L17: 1.0495191 | M17: 1.1130452
A18: Impostos indirectos líquidos | B18: Net indirect taxes | C18: pp | F18: 0.17871054 | G18: -0.35291236 | H18: 0.82765255 | I18: 0.74464174 | J18: 0.35723504 | K18: 0.715043 | L18: 0.45885027 | M18: 0.2733865
A21: Fontes: Banco de Portugal e INE. | Notas: (p) – projetado.
A22: Sources: Banco de Portugal and Statistics Portugal. | Notes: (p) - projected.

Sheet GI.1.4
A5: Índice/Contents
A6: =+Índice!$A$5 -> Boletim Económico - março 2024 / Economic Bulletin - March 2024
A7: =+Índice!$A$7 -> Parte I. Projeções para a economia portuguesa: 2024-26 / Part I. Projections for the Portuguese economy: 2024-26
A10: Gráfico I.1.4 • PIB e agregados da despesa em Portugal e na área do euro – taxa de variação média 2024-26| Em percentagem
A11: Chart I.1.4 • GDP and expenditure side aggregates in Portugal and the euro area – average rate of change 2024-26 | Percentage
G13: Por memória: Média 2015-19 | H13: Média 2024-26 (p)
E14: Unidade/unit | G14: Memorandum: 2015-19 average | H14: 2024-26 average (p)
A16: PIB | B16: PT | C16: GDP | D16: PT | E16: % | G16: 2.5699926 | H16: 2.1837095
B17: AE | D17: EA | E17: % | G17: 1.9746334 | H17: 1.2543626
A19: Consumo privado | B19: PT | C19: Private consumption | D19: PT | E19: % | G19: 2.5154342 | H19: 1.9446036
B20: AE | D20: EA | E20: % | G20: 1.7038409 | H20: 1.4126527
A22: Consumo público | B22: PT | C22: Public consumption | D22: PT | E22: % | G22: 0.91751522 | H22: 0.99940712
B23: AE | D23: EA | E23: % | G23: 1.4295846 | H23: 1.2818287
A25: FBCF | B25: PT | C25: GFCF | D25: PT | E25: % | G25: 6.305135 | H25: 4.3933992
B26: AE | D26: EA | E26: % | G26: 4.4164514 | H26: 1.0997625
A28: Exportações | B28: PT | C28: Exports | D28: PT | E28: % | G28: 5.4613035 | H28: 3.606888
B29: AE | D29: EA | E29: % | G29: 4.4448561 | H29: 2.3614353
A31: Importações | B31: PT | C31: Imports | D31: PT | E31: % | G31: 6.2151654 | H31: 3.860212
B32: AE | D32: EA | E32: % | G32: 5.2603534 | H32: 2.4406704
A34: Fontes: BCE, INE e Banco de Portugal. | Notas: (p) – projetado. As projeções para a área do euro correspondem ao exercício de projeção do BCE de março de 2024 (https://www.ecb.europa.eu/pub/projections/html/ecb.projections202403_ecbstaff~f2f2d34d5a.en.html#toc2).
A35: Sources: ECB, Statistics Portugal and Banco de Portugal. | Note: (p) – projected. The projections for the euro area refer to the ECB's staff Macroeconomic projection exercise of March 2024 (https://www.ecb.europa.eu/pub/projections/html/ecb.projections202403_ecbstaff~f2f2d34d5a.en.html#toc2).

Sheet GI.1.5
A5: Índice/Contents
A6: =+Índice!$A$5 -> Boletim Económico - março 2024 / Economic Bulletin - March 2024
A7: =+Índice!$A$7 -> Parte I. Projeções para a economia portuguesa: 2024-26 / Part I. Projections for the Portuguese economy: 2024-26
A10: Gráfico I.1.5 • Endividamento dos particulares, empresas não financeiras e administrações públicas em Portugal e na área do euro | Em percentagem do PIB
A11: Chart I.1.5 • Debt of households, non-financial corporations and public administrations in Portugal and the euro area | Percentage of GDP
A13: Unidade: % PIB
A14: Unit: % GDP
C15: 2001 | D15: 2002 | E15: 2003 | F15: 2004 | G15: 2005 | H15: 2006 | I15: 2007 | J15: 2008 | K15: 2009 | L15: 2010 | M15: 2011 | N15: 2012 | O15: 2013 | P15: 2014 | Q15: 2015 | R15: 2016 | S15: 2017 | T15: 2018 | U15: 2019 | V15: 2020 | W15: 2021 | X15: 2022 | Y15: 2023 T3
C16: 2001 | D16: 2002 | E16: 2003 | F16: 2004 | G16: 2005 | H16: 2006 | I16: 2007 | J16: 2008 | K16: 2009 | L16: 2010 | M16: 2011 | N16: 2012 | O16: 2013 | P16: 2014 | Q16: 2015 | R16: 2016 | S16: 2017 | T16: 2018 | U16: 2019 | V16: 2020 | W16: 2021 | X16: 2022 | Y16: 2023 Q3
A18: Painel A – Particulares | B18: Panel A – Households
A19: Portugal | B19: Portugal | C19: 65.235864 | D19: 69.147003 | E19: 73.21734 | F19: 77.53711 | G19: 81.589905 | H19: 85.553109 | I19: 88.504667 | J19: 90.6379 | K19: 93.929054 | L19: 92.606357 | M19: 92.26095 | N19: 92.231186 | O19: 87.812779 | P19: 83.538236 | Q19: 78.599698 | R19: 74.143461 | S19: 70.72262 | T19: 67.575891 | U19: 65.000232 | V19: 70.540996 | W19: 67.732389 | X19: 62.015143 | Y19: 57.296168
A20: Área do euro | B20: Euro area | C20: 49.345074 | D20: 50.646123 | E20: 52.560791 | F20: 54.351031 | G20: 57.047185 | H20: 58.838992 | I20: 59.60687 | J20: 60.457412 | K20: 63.865 | L20: 63.708441 | M20: 62.805646 | N20: 62.480853 | O20: 61.427911 | P20: 60.092343 | Q20: 58.822552 | R20: 58.203561 | S20: 57.483435 | T20: 57.313479 | U20: 57.401249 | V20: 61.747593 | W20: 59.546099 | X20: 56.909988
A23: Painel B – Sociedades não-financeiras | B23: Panel B – Non-financial corporations
A24: Portugal | B24: Portugal | C24: 94.580071 | D24: 94.379289 | E24: 96.717308 | F24: 95.33027 | G24: 96.602831 | H24: 98.083508 | I24: 104.4798 | J24: 112.84386 | K24: 117.60785 | L24: 117.0471 | M24: 120.57014 | N24: 126.73869 | O24: 121.70446 | P24: 113.75857 | Q24: 108.19208 | R24: 102.80363 | S24: 100.2001 | T24: 95.439938 | U24: 92.620712 | V24: 101.14969 | W24: 97.437664 | X24: 88.5505 | Y24: 82.284166
A25: Área do euro | B25: Euro area | C25: 74.276106 | D25: 74.144889 | E25: 75.377438 | F25: 74.595731 | G25: 77.286116 | H25: 80.117674 | I25: 83.675778 | J25: 88.393153 | K25: 92.586638 | L25: 91.944825 | M25: 92.431521 | N25: 92.896599 | O25: 91.100699 | P25: 90.393229 | Q25: 92.098436 | R25: 91.863732 | S25: 89.239583 | T25: 89.646477 | U25: 89.610057 | V25: 96.997077 | W25: 94.557441 | X25: 89.762436
C28: 2001 | D28: 2002 | E28: 2003 | F28: 2004 | G28: 2005 | H28: 2006 | I28: 2007 | J28: 2008 | K28: 2009 | L28: 2010 | M28: 2011 | N28: 2012 | O28: 2013 | P28: 2014 | Q28: 2015 | R28: 2016 | S28: 2017 | T28: 2018 | U28: 2019 | V28: 2020 | W28: 2021 | X28: 2022 | Y28: 2023
A29: Painel C – Administrações públicas | B29: Panel C – Public administrations
A30: Portugal | B30: Portugal | C30: 57.380219 | D30: 60.043717 | E30: 63.897284 | F30: 67.099504 | G30: 72.249078 | H30: 73.679394 | I30: 72.727965 | J30: 75.642544 | K30: 87.79906 | L30: 100.21448 | M30: 114.40307 | N30: 129.03504 | O30: 131.42974 | P30: 132.94068 | Q30: 131.17912 | R30: 131.50573 | S30: 126.14343 | T30: 121.48136 | U30: 116.60778 | V30: 134.89747 | W30: 124.54758 | X30: 112.41826 | Y30: 98.984575
A31: Área do euro | B31: Euro area | C31: 68.1 | D31: 68 | E31: 69.3 | F31: 69.6 | G31: 70.3 | H31: 68.3 | I31: 65.9 | J31: 69.6 | K31: 80.2 | L31: 85.6 | M31: 87.5 | N31: 91 | O31: 93 | P31: 93.2 | Q31: 91.3 | R31: 90.4 | S31: 88.1 | T31: 86.1 | U31: 84.1 | V31: 97.2 | W31: 94.7 | X31: 90.9 | Y31: 89.9
A33: Fontes: Banco de Portugal e BCE. | Notas: Valores consolidados. As séries de endividamento de particulares e empresas não financeiras para a área do euro têm periodicidade anual (última observação: 2022). No caso das administrações públicas, a última observação disponível para a área do euro corresponde a 2023 T3.
A34: Sources: Banco de Portugal and ECB. | Notes: Consolidated values.The euro area debt series for households and non-financial corporations are annualised (last observation: 2022). For the public administrations debt series, the last observation available for the euro area corresponds to 2023 Q3.

Sheet GI.1.6
A5: Índice/Contents
A6: =+Índice!$A$5 -> Boletim Económico - março 2024 / Economic Bulletin - March 2024
A7: =+Índice!$A$7 -> Parte I. Projeções para a economia portuguesa: 2024-26 / Part I. Projections for the Portuguese economy: 2024-26
A10: Gráfico I.1.6 • Consumo privado, rendimento disponível real e taxa de poupança
A11: Chart I.1.6 • Private consumption, real disposable income and savings rate
C12: Unidade | D12: Unit | E12: 2016 | F12: 2017 | G12: 2018 | H12: 2019 | I12: 2020 | J12: 2021 | K12: 2022 | L12: 2023 | M12: 2024 (p) | N12: 2025 (p) | O12: 2026 (p)
A14: Consumo privado | B14: Private consumption | C14: Dados encadeados em volume, em milhões de euros | D14: Chain linked volumes, million euros | E14: 122.02435 | F14: 124.58793 | G14: 127.84622 | H14: 132.01822 | I14: 122.74821 | J14: 128.55117 | K14: 135.68604 | L14: 137.90268 | M14: 140.77394 | N14: 143.48399 | O14: 146.10489
A15: Rendimento disponível real | B15: Real disposable income | C15: Dados encadeados em volume, em milhões de euros | D15: Chain linked volumes, million euros | E15: 131.24924 | F15: 133.34189 | G15: 137.115 | H15: 142.27015 | I15: 139.33862 | J15: 143.83725 | K15: 145.06643 | L15: 147.88607 | M15: 153.78489 | N15: 156.80328 | O15: 159.62067
A16: Taxa de poupança (esc. direita) | B16: Savings rate (r.h.s.) | C16: Em percentagem do rendimento disponível | D16: Percentage of disposable income | E16: 7.0285319 | F16: 6.5650436 | G16: 6.7598567 | H16: 7.2059566 | I16: 11.90654 | J16: 10.62734 | K16: 6.4662763 | L16: 6.7507289 | M16: 8.460487 | N16: 8.4942682 | O16: 8.4674355
A19: Fontes: Banco de Portugal e INE. | Nota: (p) – projetado.
A20: Sources: Banco de Portugal and Statistics Portugal. | Note: (p) – projected.

Sheet GI.1.7
A5: Índice/Contents
A6: =+Índice!$A$5 -> Boletim Económico - março 2024 / Economic Bulletin - March 2024
A7: =+Índice!$A$7 -> Parte I. Projeções para a economia portuguesa: 2024-26 / Part I. Projections for the Portuguese economy: 2024-26
A10: Gráfico I.1.7 • FBCF em percentagem do PIB | Percentagem
A11: Chart I.1.7 • GFCF percentage of GDP | Percentage
C13: Unidade/Unit | D13: 2000 | E13: 2001 | F13: 2002 | G13: 2003 | H13: 2004 | I13: 2005 | J13: 2006 | K13: 2007 | L13: 2008 | M13: 2009 | N13: 2010 | O13: 2011 | P13: 2012 | Q13: 2013 | R13: 2014 | S13: 2015 | T13: 2016 | U13: 2017 | V13: 2018 | W13: 2019 | X13: 2020 | Y13: 2021 | Z13: 2022 | AA13: 2023 | AB13: 2024 (p) | AC13: 2025 (p) | AD13: 2026 (p)
A15: FBCF total | B15: Total GFCF | C15: % | D15: 24.848814 | E15: 24.61209 | F15: 23.595373 | G15: 22.075048 | H15: 21.728076 | I15: 21.583264 | J15: 21.077413 | K15: 21.196592 | L15: 21.218611 | M15: 20.251365 | N15: 19.681436 | O15: 17.499926 | P15: 15.191621 | Q15: 14.596259 | R15: 14.812947 | S15: 15.41353 | T15: 15.493265 | U15: 16.688141 | V15: 17.228985 | W15: 17.68285 | X15: 18.863619 | Y15: 19.278872 | Z15: 18.587558 | AA15: 18.616569 | AB15: 18.904055 | AC15: 19.484754 | AD15: 19.849034
A16: FBCF pública | B16: Public GFCF | C16: % | D16: 4.2199233 | E16: 4.6483026 | F16: 4.2763878 | G16: 4.1215508 | H16: 4.1691025 | I16: 3.856509 | J16: 3.1777109 | K16: 3.0668756 | L16: 3.4803788 | M16: 3.941604 | N16: 5.0675423 | O16: 3.3177071 | P16: 2.375338 | Q16: 2.1519388 | R16: 1.9675556 | S16: 2.242846 | T16: 1.5419046 | U16: 1.7720809 | V16: 1.8033576 | W16: 1.7652773 | X16: 2.2615707 | Y16: 2.4468567 | Z16: 2.1786811 | AA16: 2.4042469 | AB16: 2.6426301 | AC16: 2.8484384 | AD16: 2.8556879
A17: FBCF residencial | B17: Residential GFCF | C17: % | D17: 7.7060372 | E17: 7.3226399 | F17: 7.0162557 | G17: 5.9999625 | H17: 5.8292267 | I17: 5.8201641 | J17: 5.3245693 | K17: 4.9037369 | L17: 4.2478582 | M17: 3.7326928 | N17: 3.4165304 | O17: 3.0478115 | P17: 2.9361341 | Q17: 2.5476179 | R17: 2.5122854 | S17: 2.5019207 | T17: 2.6152356 | U17: 2.734291 | V17: 2.8313415 | W17: 2.8165809 | X17: 2.8336877 | Y17: 3.078137 | Z17: 2.9702712 | AA17: 2.8739712 | AB17: 2.8037936 | AC17: 2.7912645 | AD17: 2.7986456
A18: FBCF privada não residencial | B18: Private-sector non-residential GFCF | C18: % | D18: 12.922853 | E18: 12.641148 | F18: 12.302729 | G18: 11.953534 | H18: 11.729747 | I18: 11.906591 | J18: 12.575133 | K18: 13.22598 | L18: 13.490374 | M18: 12.577068 | N18: 11.197364 | O18: 11.134407 | P18: 9.880149 | Q18: 9.8967026 | R18: 10.333106 | S18: 10.668764 | T18: 11.336125 | U18: 12.181769 | V18: 12.594286 | W18: 13.100991 | X18: 13.76836 | Y18: 13.753878 | Z18: 13.438606 | AA18: 13.338351 | AB18: 13.457632 | AC18: 13.845051 | AD18: 14.1947
A21: Fontes: Banco de Portugal e INE. | Notas: (p) projetado. Rácio do investimento sobre o PIB, dados encadeados em volume (base 2016).
A22: Sources: Banco de Portugal and Statistics Portugal. | Notes: (p) - projected. Investment to GDP ratio, chain linked volumes (2016).

Sheet GI.1.8
A5: Índice/Contents
A6: =+Índice!$A$5 -> Boletim Económico - março 2024 / Economic Bulletin - March 2024
A7: =+Índice!$A$7 -> Parte I. Projeções para a economia portuguesa: 2024-26 / Part I. Projections for the Portuguese economy: 2024-26
A10: Gráfico I.1.8 • Balança corrente e de capital| Em percentagem do PIB
A11: Chart I.1.8 • Current and capital account | Percentage of GDP
D13: Unidade/unit | E13: 2001 | F13: 2002 | G13: 2003 | H13: 2004 | I13: 2005 | J13: 2006 | K13: 2007 | L13: 2008 | M13: 2009 | N13: 2010 | O13: 2011 | P13: 2012 | Q13: 2013 | R13: 2014 | S13: 2015 | T13: 2016 | U13: 2017 | V13: 2018 | W13: 2019 | X13: 2020 | Y13: 2021 | Z13: 2022 | AA13: 2023 | AB13: 2024 (p) | AC13: 2025 (p) | AD13: 2026 (p)
A15: Balança corrente e de capital | B15: Current and capital account | D15: % | E15: -8.9133228 | F15: -6.4957542 | G15: -4.4388352 | H15: -6.2394112 | I15: -8.1620089 | J15: -9.070667 | K15: -8.4784722 | L15: -10.62894 | M15: -9.1274675 | N15: -8.8654226 | O15: -4.4829763 | P15: 0.46765212 | Q15: 3.2883846 | R15: 1.4769496 | S15: 1.4773052 | T15: 2.0876594 | U15: 2.1500439 | V15: 1.5474591 | W15: 1.3235582 | X15: -0.051471457 | Y15: 0.9584793 | Z15: -0.20254121 | AA15: 2.7255972 | AB15: 3.595957 | AC15: 3.8835519 | AD15: 4.08046
A16: Balança de bens | B16: Goods account | D16: % | E16: -12.81871 | F16: -10.875434 | G16: -9.1812796 | H16: -10.801884 | I16: -11.399418 | J16: -11.249533 | K16: -11.421162 | L16: -13.398861 | M16: -10.358466 | N16: -10.848176 | O16: -8.2332002 | P16: -5.5535012 | Q16: -4.7667925 | R16: -5.5874448 | S16: -5.4230871 | T16: -5.3687058 | U16: -6.7918982 | V16: -7.623305 | W16: -7.5972319 | X16: -6.2377506 | Y16: -7.4275571 | Z16: -10.907819 | AA16: -9.3102581 | AB16: -9.3592208 | AC16: -9.4321019 | AD16: -9.291397
A17: Balança de serviços | B17: Services account | D17: % | E17: 2.7692818 | F17: 2.8060698 | G17: 2.8302553 | H17: 3.0679075 | I17: 2.8678941 | J17: 3.4659391 | K17: 4.1201951 | L17: 4.1503448 | M17: 3.5932637 | N17: 3.5166424 | O17: 4.5260003 | P17: 5.5552656 | Q17: 6.5069952 | R17: 6.3800646 | S17: 6.8253161 | T17: 7.0710723 | U17: 8.2569825 | V17: 8.5244645 | W17: 8.3729701 | X17: 4.3012241 | Y17: 4.8602074 | Z17: 8.9758785 | AA17: 10.542982 | AB17: 10.484159 | AC17: 10.662495 | AD17: 10.770484
A18: Balanças de rendimento e capital | B18: Income and capital accounts | D18: % | E18: 1.1361057 | F18: 1.5736098 | G18: 1.9121891 | H18: 1.4945655 | I18: 0.36951521 | J18: -1.2870734 | K18: -1.1775056 | L18: -1.3804242 | M18: -2.3622654 | N18: -1.5338886 | O18: -0.77577642 | P18: 0.46588773 | Q18: 1.5481819 | R18: 0.68432976 | S18: 0.075076272 | T18: 0.38529293 | U18: 0.68495957 | V18: 0.64629955 | W18: 0.54782001 | X18: 1.885055 | Y18: 3.525829 | Z18: 1.7293993 | AA18: 1.4928729 | AB18: 2.4710191 | AC18: 2.6531593 | AD18: 2.6013727
A21: Fontes: Banco de Portugal e INE. | Notas: (p) – projetado.
A22: Sources: Banco de Portugal and Statistics Portugal. | Notes: (p) - projected.

Sheet GI.1.9
A5: Índice/Contents
A6: =+Índice!$A$5 -> Boletim Económico - março 2024 / Economic Bulletin - March 2024
A7: =+Índice!$A$7 -> Parte I. Projeções para a economia portuguesa: 2024-26 / Part I. Projections for the Portuguese economy: 2024-26
A10: Gráfico I.1.9 • Variação de postos de trabalho entre 2019 e 2023 e remuneração média mensal em 2023 - por intensidade tecnológica e de conhecimento | Em milhares e em euros
A11: Chart I.1.9 • Change in jobs between 2019 and 2023 and average monthly wages in 2023 - by technological and knowledge intensity | Thousands and euros
E13: Total da economia | F13: Indústrias de alta e média tecnologia e Serviços intensivos em conhecimento | G13: Indústrias de baixa tecnologia e Serviços pouco intensivos em conhecimento | H13: Outros setores
E14: Total economy | F14: High- and medium-tech industries and knowledge-intensive services | G14: Low-tech industries and low knowledge-intensive services | H14: Other sectors
C15: Unidade | D15: unit | E15: (100) | F15: (47) | G15: (42) | H15: (11)
A17: Variação de postos de trabalho - 2023 vs. 2019 | B17: Change in jobs - 2023 vs. 2019 | C17: Milhares de postos de trabalho | D17: Thousands of jobs | E17: 456.7 | F17: 215.8 | G17: 148.3 | H17: 92.6
A18: Remuneração média mensal - 2023 (esc. direita) | B18: Average monthly wages - 2023 (r.h.s.) | C18: Euros | D18: Euros | E18: 1505 | F18: 1803.0773 | G18: 1263.569 | H18: 1165.1551
A21: Fonte: INE (com base em informação da Segurança Social e Caixa Geral de Aposentações). | Notas: A informação apresentada relativa aos postos de trabalho e à remuneração média por intensidade tecnológica e de conhecimento foi obtida através da classificação da atividade económica das empresas. Indústrias de alta e média tecnologia e Serviços intensivos em conhecimento – inclui a Indústria transformadora com exceção das indústrias alimentar, têxtil, madeira e papel e os Serviços de transporte de água e aéreos, de informação e de comunicação, financeiros e seguros, de consultoria e científicos, Administração Pública, Saúde e Educação, Atividades artísticas. Indústrias de baixa tecnologia e Serviços pouco intensivos em conhecimento – inclui as Indústrias alimentar, têxtil, madeira e papel e os Serviços de armazenagem, transportes terrestres, Alojamento e restauração e Outros serviços. Outros setores - inclui: Agricultura, silvicultura e pesca, Indústrias extrativas, Energia e Construção. Os valores entre parêntesis correspondem à percentagem do emprego em cada setor no emprego total da economia em 2023.
A22: Source: Statistics Portugal (based on information from Social Security and Caixa Geral de Aposentações). | Notes: the information presented on jobs and average wages by technological and knowledge intensity was obtained through classifying companies by economic activity. High- and medium-tech industries and knowledge-intensive services - includes Manufacturing, with the exception of Food, Textiles, Wood and Paper, Water and air transport, Information and communication, Financial and insurance, Consultancy and scientific services, Public administration, Health and education, Artistic activities. Low-tech industries and services that are low knowledge-intensive - includes food, textiles, wood and paper industries and storage services, land transport, accommodation and food services and other services. Other sectors - includes: Agriculture, forestry and fishing, Mining and quarrying, Energy and Construction. The values in brackets correspond to the share of each sector in the economy's total employment in 2023.

Sheet QC1.1
A5: Índice/Contents
A6: =+Índice!$A$5 -> Boletim Económico - março 2024 / Economic Bulletin - March 2024
A7: =+Índice!$A$29 -> Caixa 1- Enquadramento e políticas / Box 1-External environment, financing conditions and policies
A10: Quadro C1.1 • Hipóteses do exercício de projeção
A11: Table C1.1 • Eurosystem staff projection assumptions
E13: BE março 2024 | I13: Revisões face ao BE dezembro 2023
C14: Unidade | D14: Unit | E14: EB March 2024 | I14: Revisions from EB December 2023
E15: 2023 | F15: 2024 | G15: 2025 | H15: 2026 | I15: 2023 | J15: 2024 | K15: 2025 | L15: 2026
A17: Enquadramento internacional | B17: International environment
A18: PIB mundial | B18: World GDP | C18: tva | D18: yoy | E18: 3.1132813 | F18: 3.0306096 | G18: 3.0380423 | H18: 3.0372859 | I18: 0.13105938 | J18: 0.22196955 | K18: 0.04499832 | L18: 0.010746717
A19: PIB Área do euro | B19: Euro area GDP | C19: tva | D19: yoy | E19: 0.5 | F19: 0.6 | G19: 1.5 | H19: 1.6 | I19: -0.061546105 | J19: -0.24940954 | K19: -0.025214233 | L19: 0.056078019
A20: Comércio mundial | B20: World trade | C20: tva | D20: yoy | E20: 0.55748729 | F20: 2.3258895 | G20: 3.1307363 | H20: 3.2328624 | I20: -0.17036155 | J20: -0.42342613 | K20: 0.084163578 | L20: 0.14114455
A21: Procura externa | B21: External demand | C21: tva | D21: yoy | E21: -0.46342756 | F21: 1.5468758 | G21: 3.1400998 | H21: 3.1352816 | I21: -0.12955271 | J21: -0.48779565 | K21: 0.1178946 | L21: 0.21999729
A23: Preços internacionais | B23: International prices
A24: Preço do petróleo | B24: Oil prices | C24: vma | D24: aav | E24: 77.451136 | F24: 73.749327 | G24: 69.332302 | H24: 66.840435 | I24: -0.28959686 | J24: -0.16370936 | K24: -1.2978501 | L24: -1.0849984
A25: Preço do gás (MWh) | B25: Gas prices (MWh) | C25: vma | D25: aav | E25: 40.613095 | F25: 29.98618 | G25: 32.086875 | H25: 29.541692 | I25: -0.91096472 | J25: -17.403778 | K25: -12.082983 | L25: -7.341225
A26: Matérias-primas não energéticas | B26: Non-oil commodity prices | C26: tva | D26: yoy | E26: -14.529676 | F26: 0.62146628 | G26: 2.0979264 | H26: 0.069662752 | I26: 0.68728707 | J26: 3.2083115 | K26: -0.34037183 | L26: -1.607026
A27: Preço de importação dos concorrentes | B27: Competitors' import prices | C27: tva | D27: yoy | E27: -1.3084794 | F27: 1.038034 | G27: 2.644447 | H27: 2.4174107 | I27: -0.29985759 | J27: -0.92467597 | K27: -0.0082151102 | L27: 0.17440592
A29: Condições monetárias e financeiras | B29: Monetary and financial conditions
A30: Taxa de juro de curto prazo (EURIBOR a 3 meses) | B30: Short-term interest rate (3-month EURIBOR) | C30: % | D30: % | E30: 3.4308006 | F30: 3.4278973 | G30: 2.4458333 | H30: 2.3529167 | I30: -0.0043677092 | J30: -0.17460263 | K30: -0.39458334 | L30: -0.33500004
A31: Taxa de juro implícita da dívida pública portuguesa | B31: Implicit interest rate in portuguese public debt | C31: % | D31: % | E31: 2.1169839 | F31: 2.3353418 | G31: 2.3544669 | H31: 2.4016181 | I31: 0.02488075 | J31: 0.018396698 | K31: 0.00172273 | L31: -0.012677878
A32: Índice de taxa de câmbio efetiva | B32: Effective exchange rate index | C32: tva | D32: yoy | E32: 4.8827668 | F32: 1.0657872 | G32: -0.033893056 | H32: 0 | I32: -0.023350962 | J32: -0.31553381 | K32: -0.033893056 | L32: 0
A33: Taxa de câmbio euro-dólar | B33: Euro-dollar exchange rate | C33: vma | D33: aav | E33: 1.0813067 | F33: 1.0808436 | G33: 1.07998 | H33: 1.07998 | I33: 0.0006369475 | J33: -0.0027564062 | K33: -0.00362 | L33: -0.00362
A36: Fontes: Banco de Portugal e Eurosistema (cálculos do Banco de Portugal). | Notas: tva – taxa de variação anual, % – em percentagem, vma – valor médio anual, MWh – megawatt-hora. As hipóteses técnicas e de enquadramento externo e as projeções para o PIB e inflação da área do euro coincidem com as do exercício de projeção do BCE divulgado a 7 de março (ver “Projeções macroeconómicas para a área do euro elaboradas por especialistas do Eurosistema”, março de 2024), incluindo a informação disponível até 12 de fevereiro. Os preços internacionais são medidos em euros. A hipótese técnica para o preço do petróleo, gás e matérias-primas não energéticas assenta nos mercados de futuros. O preço de importação dos concorrentes corresponde a uma média ponderada dos deflatores de exportação dos países dos quais Portugal importa, ponderada pelo peso relativo nas importações portuguesas (para mais informação, ver “Trade consistency in the context of the Eurosystem projection exercises: an overview”, ECB Ocasional Paper 108, março de 2010). A evolução da taxa EURIBOR a 3 meses tem por base as expetativas implícitas nos contratos de futuros. A taxa de juro implícita da dívida pública é calculada como o rácio entre a despesa em juros do ano e a média simples do stock da dívida no final do ano e no final do ano anterior. Um aumento da taxa de câmbio corresponde a uma apreciação. O índice de taxa de câmbio efetiva do euro é calculado face a um grupo de 41 países parceiros. A revisão da taxa de câmbio euro-dólar é apresentada em percentagem. A hipótese técnica para as taxas de câmbio bilaterais pressupõe a manutenção ao longo do horizonte de projeção dos níveis médios observados nas duas semanas anteriores à data de fecho da informação.
A37: Sources: Banco de Portugal and Eurosystem (Banco de Portugal calculations). | Notes: yoy – year-on-year rate of change, % – in percentage, aav – annual average value, MWh – megawatt-hour. Technical and external environment assumptions, as well as projections for euro area GDP and inflation, coincide with those in the ECB projection exercise released on March 7 ("Eurosystem staff macroeconomic projections for the euro area", March 2024), which include information up to February 12. International prices are in euros. The technical assumption for the price of oil, gas and non-energy commodities is based on futures markets. The import price of competitors corresponds to a weighted average of the export deflators of the countries from which Portugal imports, weighted by their share on total Portuguese imports (for more information, see "Trade consistency in the context of the Eurosystem projection exercises: an overview", ECB Occasional Paper 108, March 2010). The evolution of the 3-month EURIBOR is based on expectations implied in futures contracts. The implicit interest rate on public debt is computed as the ratio of interest expenditure for the year to the simple average of the stock of debt at the end of the same year and at the end of the preceding year. An increase in the exchange rate corresponds to an appreciation of the euro. The effective exchange rate of the euro is computed against 41 trading partner countries. Revisions in the euro-dollar exchange rate are in percentage. The technical assumption for bilateral exchange rates assumes that the average levels observed in the two weeks prior to the cut-off date are maintained over the projection horizon.

Sheet GC1.1
A5: Índice/Contents
A6: =+Índice!$A$5 -> Boletim Económico - março 2024 / Economic Bulletin - March 2024
A7: =+Índice!$A$29 -> Caixa 1- Enquadramento e políticas / Box 1-External environment, financing conditions and policies
A10: Gráfico C1.1 • PIB da área do euro e maiores países | Taxa de variação anual
A11: Chart C1.1 • Euro area and major countries GDP | Annual rate of change
C14: Área do euro | D14: Alemanha | E14: França | F14: Itália | G14: Espanha
B15: Unidade/unit | C15: Euro area | D15: Germany | E15: France | F15: Italy | G15: Spain
A17: 2020 | B17: % | C17: -6.2447671 | D17: -4.1974209 | E17: -7.6786926 | F17: -9.0496266 | G17: -11.167321
A18: 2021 | B18: % | C18: 5.889132 | D18: 3.1243151 | E18: 6.364221 | F18: 8.2783689 | G18: 6.4031926
A19: 2022 | B19: % | C19: 3.4622487 | D19: 1.8814451 | E19: 2.5261547 | F19: 4.1451845 | G19: 5.770717
A20: 2023 | B20: % | C20: 0.53539515 | D20: -0.10871221 | E20: 0.86885782 | F20: 1.01723 | G20: 2.5016792
A23: Fonte: Eurostat (cálculos do Banco de Portugal).
A24: Source: Eurostat (Banco de Portugal calculations).

Sheet QC2.1
A5: Índice/Contents
A6: =+Índice!$A$5 -> Boletim Económico - março 2024 / Economic Bulletin - March 2024
A7: =+Índice!$A$35 -> Caixa 2 - Expetativas de taxas de juro e de consumo das famílias / Box 2 - Consumers' expectations on interest rates and consumption
A10: Quadro C2.1 • Características dos consumidores inquiridos | Valores médios e percentagem
A11: Table C2.1 • Characteristics of the surveyed consumers | Mean values and percentage
C14: Unidade/Unit | D14: Com crédito à habitação | E14: Sem crédito à habitação | F14: Todos os consumidores
D15: With mortgage | E15: Withouth mortgage | F15: All consumers
A16: Idade | B16: Age | C16: Anos / Years | D16: 41.5 | E16: 40.6 | F16: 40.9
A17: Educação | B17: Education | C17: Percentagem com ensino superior / Percentage with higher education | D17: 57 | E17: 51 | F17: 54
A18: Rendimento anual | B18: Yearly income | C18: Euros / Euro | D18: 25562.9 | E18: 21894.9 | F18: 23330.3
A19: Poupanças nos últimos 3 meses | B19: Savings in the last 3 months | C19: Euros / Euro | D19: 1011.5 | E19: 1256.8 | F19: 1157.6
A20: Número de famílias | B20: Number of aggregates | C20: Número e percentagem / Number and percentage | D20: 1599 (39%) | E20: 2487 (61%) | F20: 4086 (100%)
A23: Fonte: Inquérito sobre as Expetativas dos Consumidores (BCE). | Nota: Os valores médios da idade, do rendimento e da poupança são calculados com o ponto médio de cada intervalo de resposta. Para a idade, existem quatro intervalos: 18-34, 35-54, 55-70 e +70. Para a educação, existem três níveis de resposta: Ensino Básico, Secundário e Superior. Para o rendimento anual e para a poupança existem 10 intervalos de resposta. A definição da situação relativamente ao crédito à habitação de cada consumidor é construída através da questão: “Qual das seguintes opções melhor descreve a sua (e do seu agregado familiar) residência?”.
A24: Sources: Consumer Expectations Survey (ECB). | Note: The mean values for age, income and savings are computed with the mean value of each bracket. For age, there are four brackets: 18-34, 35-54, 55-70 and +70. For education, there are three possible respondes: Primary Education, Secondary Education and Higher Education. For the yearly income and for savings there are 10 possible brackets. The classification by housing type for each consumer is done with the question: "Which of the following describes your (and your family’s) main place of residence?".

Sheet GC2.1
A5: Índice/Contents
A6: =+Índice!$A$5 -> Boletim Económico - março 2024 / Economic Bulletin - March 2024
A7: =+Índice!$A$35 -> Caixa 2 - Expetativas de taxas de juro e de consumo das famílias / Box 2 - Consumers' expectations on interest rates and consumption
A10: Gráfico C2.1 • Situação financeira dos consumidores em Portugal total e por situação de crédito | Saldo de respostas extremas
A11: Chart C2.1 • Consumers' financial situation in Portugal in total and by housing type | Net percentage
A13: Unidade/Unit
C14: Meses | D14: abr 2022 | E14: mai 2022 | F14: jun 2022 | G14: jul 2022 | H14: ago 2022 | I14: set 2022 | J14: out 2022 | K14: nov 2022 | L14: dez 2022 | M14: jan 2023 | N14: fev 2023 | O14: mar 2023 | P14: abr 2023 | Q14: mai 2023 | R14: jun 2023 | S14: jul 2023 | T14: ago 2023 | U14: set 2023 | V14: out 2023 | W14: nov 2023 | X14: dez 2023
C15: Months | D15: apr 2022 | E15: may 2022 | F15: jun 2022 | G15: jul 2022 | H15: aug 2022 | I15: sep 2022 | J15: oct 2022 | K15: nov 2022 | L15: dec 2022 | M15: jan 2023 | N15: feb 2023 | O15: mar 2023 | P15: apr 2023 | Q15: may 2023 | R15: jun 2023 | S15: jul 2023 | T15: aug 2023 | U15: sep 2023 | V15: oct 2023 | W15: nov 2023 | X15: dec 2023
B17: Painel A - Últimos 12 meses | C17: Panel A: Last 12 months
A18: S.R.E / Net percentage | B18: Todos os consumidores | C18: All consumers | D18: -45.543541 | E18: -47.099003 | F18: -52.714321 | G18: -47.820717 | H18: -47.417629 | I18: -51.71402 | J18: -55.701748 | K18: -54.805828 | L18: -55.360119 | M18: -52.654766 | N18: -54.864407 | O18: -55.618893 | P18: -51.978989 | Q18: -47.580296 | R18: -44.827164 | S18: -39.573837 | T18: -36.420158 | U18: -43.632675 | V18: -40.416271 | W18: -40.733833 | X18: -39.576805
A19: S.R.E / Net percentage | B19: Com crédito à habitação | C19: With mortgage | D19: -49.086838 | E19: -50.23686 | F19: -53.551596 | G19: -51.256279 | H19: -47.466251 | I19: -57.600185 | J19: -63.169003 | K19: -61.725046 | L19: -58.387814 | M19: -55.188545 | N19: -57.007074 | O19: -56.342489 | P19: -59.840986 | Q19: -54.828539 | R19: -53.267044 | S19: -49.881516 | T19: -49.685043 | U19: -46.499666 | V19: -47.851738 | W19: -49.505829 | X19: -43.798344
A20: S.R.E / Net percentage | B20: Sem crédito à habitação | C20: Without mortgage | D20: -43.651447 | E20: -45.448654 | F20: -52.255856 | G20: -45.921253 | H20: -47.393082 | I20: -48.893433 | J20: -51.892166 | K20: -51.032829 | L20: -53.808918 | M20: -51.412457 | N20: -53.795105 | O20: -55.264065 | P20: -48.006702 | Q20: -43.439953 | R20: -40.074997 | S20: -33.523422 | T20: -29.04187 | U20: -42.128601 | V20: -36.34288 | W20: -36.045994 | X20: -37.296978
B22: Painel B - Próximos 12 meses | C22: Panel B: Next 12 months
A23: S.R.E / Net percentage | B23: Todos os consumidores | C23: All consumers | D23: -30.723333 | E23: -31.459055 | F23: -37.083076 | G23: -31.759291 | H23: -30.716162 | I23: -36.375626 | J23: -42.163052 | K23: -36.766991 | L23: -35.454388 | M23: -33.602627 | N23: -27.440767 | O23: -27.142879 | P23: -19.131081 | Q23: -15.568834 | R23: -14.746832 | S23: -11.816614 | T23: -13.945408 | U23: -15.686953 | V23: -20.116486 | W23: -18.63155 | X23: -16.817703
A24: S.R.E / Net percentage | B24: Com crédito à habitação | C24: With mortgage | D24: -41.247543 | E24: -39.749611 | F24: -36.712227 | G24: -34.230743 | H24: -33.056908 | I24: -47.320572 | J24: -49.144672 | K24: -46.578545 | L24: -42.981792 | M24: -38.870605 | N24: -36.662086 | O24: -31.936535 | P24: -29.315941 | Q24: -21.366671 | R24: -19.665657 | S24: -20.641647 | T24: -25.382534 | U24: -21.743393 | V24: -25.594881 | W24: -22.795879 | X24: -14.140606
A25: S.R.E / Net percentage | B25: Sem crédito à habitação | C25: Without mortgage | D25: -25.10347 | E25: -27.098646 | F25: -37.286144 | G25: -30.39286 | H25: -29.534441 | I25: -31.13092 | J25: -38.601227 | K25: -31.416819 | L25: -31.597834 | M25: -31.019756 | N25: -22.838858 | O25: -24.792246 | P25: -13.985161 | Q25: -12.256998 | R25: -11.977232 | S25: -6.6364956 | T25: -7.5837669 | U25: -12.509634 | V25: -17.11524 | W25: -16.406094 | X25: -18.263462
A28: Fonte: Inquérito sobre as Expetativas dos Consumidores (BCE). | Notas: As questões correspondentes são, respetivamente: “A situação financeira do seu agregado familiar está melhor ou pior do que estava há 12 meses?” (Painel A) e “Em termos prospetivos, a situação financeira do seu agregado familiar estará melhor ou pior em 12 meses?” (Painel B). A definição da situação relativamente ao crédito à habitação de cada consumidor é construída através da questão: “Qual das seguintes opções melhor descreve a sua (e do seu agregado familiar) residência?”. O saldo de respostas extremas é calculado como a diferença entre a percentagem de respostas “Melhoria” e “Deterioração”. As estatísticas apresentadas são calculadas com ponderadores mensais que garantem a representatividade da amostra com a estrutura demográfica da população.
A29: Sources: Consumer Expectations Survey (ECB). | Notes: The corresponding questions are, respectively: "Do you think your household is financially better off or worse off now than it was 12 months ago?" (Panel A) and "And looking ahead, do you think your household will be financially better off or worse off in 12 months from now than it is today?" (Panel B). The classification by housing type for each consumer is done with the question: "Which of the following describes your (and your family’s) main place of residence?". The net percentage is calculated as the difference between the percentage of "better off" and "worse off" responses. The presented statistics are calculated using monthly weights that ensure the representativeness of the sample with the demographic structure of the population.

Sheet GC2.2
A5: Índice/Contents
A6: =+Índice!$A$5 -> Boletim Económico - março 2024 / Economic Bulletin - March 2024
A7: =+Índice!$A$35 -> Caixa 2 - Expetativas de taxas de juro e de consumo das famílias / Box 2 - Consumers' expectations on interest rates and consumption
A10: Gráfico C2.2 • Impacto do aumento de 1 pp nas expetativas de taxas de juro sobre as expetativas de consumo nos 12 meses seguintes | Pontos percentuais
A11: Chart C2.2 • Impact of an increase of 1 pp of expectatations for interest rates on spending expectations in the next 12 months | Percentage points
A14: Unidade/Unit | D14: Coeficiente | E14: Limite inferior do intervalo de confiança | F14: Limite superior do intervalo de confiança
D15: Coefficient | E15: Lower bound of the confidence interval | F15: Upper bound of the confidence interval
B17: Painel A: Expetativas de taxas de juro no crédito à habitação | C17: Panel A: Expectations on interest rates of mortgages
A18: Pontos percentuais/Percentage points | B18: Todos os consumidores | C18: All consumers | D18: -0.2251589 | E18: -0.168 | F18: -0.1108411
A19: Pontos percentuais/Percentage points | B19: Com crédito à habitação | C19: With mortgage | D19: -0.7680296 | E19: -0.668 | F19: -0.5679704
A20: Pontos percentuais/Percentage points | B20: Sem crédito à habitação | C20: Without mortgage | D20: 0.0034253 | E20: 0.072632 | F20: 0.1418387
B22: Painel B: Expetativas de taxas de juro nos depósitos | C22: Panel B: Expectations on interest rates of savings accounts
A23: Pontos percentuais/Percentage points | B23: Todos os consumidores | C23: All consumers | D23: 0.132793 | E23: 0.285304 | F23: 0.437815
A24: Pontos percentuais/Percentage points | B24: Com crédito à habitação | C24: With mortgage | D24: -0.0354244 | E24: 0.2240634 | F24: 0.4835512
A25: Pontos percentuais/Percentage points | B25: Sem crédito à habitação | C25: Without mortgage | D25: 0.1290993 | E25: 0.3176151 | F25: 0.5061309
A28: Fonte: Inquérito sobre as Expetativas dos Consumidores (BCE) e cálculos do Banco de Portugal. | Notas: Cada barra mostra a elasticidade das expetativas de consumo real a uma alteração nas expetativas de taxa de juro no crédito à habitação (Painel A) e nos depósitos (Painel B) de 1%. Os intervalos de confiança correspondem a um nível de confiança de 95%. O intervalo temporal inclui os dados de abril de 2022 até dezembro de 2023. As questões correspondentes são: “Quanto é que os gastos do seu agregado familiar com todos os bens e serviços irão mudar nos próximos 12 meses?” para as expetativas sobre o crescimento nominal do consumo; “Nos próximos 12 meses, o que espera que aconteça com o rendimento líquido total do seu agregado familiar (após impostos e deduções obrigatórias)?” para as expetativas sobre o crescimento nominal do rendimento; “Daqui a 12 meses, qual é será o valor das taxas de juro nos créditos à habitação do país em que reside?” para as expetativas de taxa de juro no crédito à habitação e “Daqui a 12 meses, qual é será a taxa de juro nos depósitos do país em que reside?” para as expetativas de taxa de juro nos depósitos. Foram apenas consideradas as respostas as estas duas últimas perguntas entre o 5º e 95º percentil para cada país e mês.
A29: Sources: Consumer Expectations Survey (ECB) and calculations by Banco de Portugal. | Notes: Each bar shows the elasticity of real spending expectations to a 1% change in expectations of interest rates on mortgages (Panel A) and interest rates on saving accounts (Panel B). Confidence intervals correspond to a confidence level of 95%. The time interval includes data from April 2022 to December 2023. The corresponding questions are: "By what percent do you expect your household spending on all goods and services to change during the next 12 months compared with your spending in the past 12 months?" for expectations about nominal consumption growth; "By about what percentage do you expect the total net income (that is after tax and compulsory deductions) of your household to change?" for expectations about nominal income growth; "In 12 months from now, what do you think will be the interest rate on mortgages in the country you currently live in?" for expectations for interest rates on mortgages, and "In 12 months from now, what do you think will be the interest rate on savings accounts in the country you currently live in?" for expectations for interest rates on savings accounts. Only responses to the last two questions were considered between the 5th and 95th percentiles for each country and month.

Sheet QC3.1
A5: Índice/Contents
A6: =+Índice!$A$5 -> Boletim Económico - março 2024 / Economic Bulletin - March 2024
A7: =+Índice!$A$43 -> Caixa 3 - Evolução dos empréstimos às empresas na sequência das medidas de apoio ao crédito na pandemia / Box 3 - Evolution of corporate loans following the credit support measures during the pandemic
A10: Quadro C3.1 • Características das empresas dos grupos analisados em 2019 | Valores médios
A11: Table C3.1 • Firm Characteristics by group in 2019 | Mean values
C13: Com garantia pública e com moratória | D13: Com garantia pública e sem moratória | E13: Sem garantia pública e com moratória | F13: Sem garantia pública e sem moratória
C14: With public guarantees and with moratorium | D14: With public guarantees and without moratorium | E14: Without public guarantees and with moratorium | F14: Without public guarantees and without moratorium
F15: Totais | G15: Elegíveis
F16: Total | G16: Eligible
A18: Ativo (1000 euros) | B18: Total assets (1000 euros) | C18: 1875.6 | D18: 934.5 | E18: 1209.6 | F18: 917.3 | G18: 822.9
A19: Turnover (1000 euros) | B19: Turnover (1000 euros) | C19: 1673.9 | D19: 1066.7 | E19: 708.1 | F19: 683 | G19: 627.9
A20: Número de empregados | B20: Number of workers | C20: 16.6 | D20: 10.5 | E20: 7.5 | F20: 6.4 | G20: 6.8
A21: Dívida (1000 euros) | B21: Total Debt (1000 euros) | C21: 636 | D21: 193.6 | E21: 434.6 | F21: 203.5 | G21: 176.1
A22: Empresa exportadora | B22: Exporting firms | C22: 0.651 | D22: 0.444 | E22: 0.337 | F22: 0.292 | G22: 0.292
A23: Idade | B23: Age | C23: 16.7 | D23: 15.2 | E23: 13.3 | F23: 14 | G23: 13.7
A24: EBIT/Ativo (%) | B24: EBIT/Assets (%) | C24: 4.5 | D24: 6.8 | E24: 3 | F24: 5.1 | G24: 5.5
A25: Dívida/Ativo (%) | B25: Debt/Assets (%) | C25: 33.9 | D25: 20.7 | E25: 35.9 | F25: 22.2 | G25: 21.4
A26: Número de empresas | B26: Number of firms | C26: 24200 | D26: 30805 | E26: 34123 | F26: 132229 | G26: 123 697
A28: Fontes: Banco de Portugal. | Notas: Dados da Central de Balanços. Distinguem-se quatro grupos de empresas: (i) empresas com crédito com garantia pública e que beneficiaram das moratórias, (ii) empresas com crédito com garantia pública e que não beneficiaram das moratórias, (iii) empresas sem crédito com garantia pública e que beneficiaram das moratórias e (iv) empresas sem crédito com garantia pública e que não beneficiaram das moratórias. O útimo grupo inclui o sub-conjunto das empresas sem garantia pública e sem moratória, mas que eram elegíveis para ambas as medidas. EBIT/Ativo e Dívida/Ativo são calculados como média ponderada.
